Workbook

Sheet AMBERIEU LAGNIEU
A2: Accompagnement des bénéficiaires du RSA - "CIP +" / 2025 | J2: Sortie + sous objectif (les noter en vert tant que vous les garder en suivi dans l'emploi)
A3: Territoire: CDS…. - LOT .../ CLPE ZONE … | J3: suspension remob
A5: Accompagnement des bénéficiaires du RSA - "CIP +" / 2025 | J5: Sortie + sous objectif (les noter en vert tant que vous les garder en suivi dans l'emploi)
A6: Territoire: CDS AMBERIEU/MEXIMIEUX…. - LOT 3.../ CLPE ZONE 3 | J6: suspension remob
A7: Nom de l'OPERATEUR : ALFA3A | J7: Cli
A8: CIP : HELENE VRAINE (arret à partir du 13/3 - arrivée Aviva le | H8: NOMBRE DE BRSA | I8: =+SUM(A12:A310) -> 115 | S8: SORTIES DU DISPOSITIF | X8: Positionnement actions / démarches
J9: DATE | M9: FREINS IDENTIFIES | U9: SORTIES + sous objectif
B10: H/F | C10: NOM | D10: PRENOM | E10: âge | F10: Niveau scolaire | G10: CDS | H10: DATE ORIENTATION | I10: DATE 1ER RDV fixé | J10: C.E SIGNE | K10: FIN CE 6 MOIS | L10: BILAN PARCOURS (7eme mois) | M10: 1 | N10: 2 | O10: autre | P10: NOMBRE D OFFRES D EMPLOI PROPOSEES (OE/INFO COLL/jobdating..) | Q10: NBRE D ENTRETIENS DE RECRUTEMENT OBTENUS SUITE A VOS OFFRES D EMPLOI | R10: PMSMP (1 = oui) | S10: Motif de sortie | T10: MOTIF de la REO | U10: types | V10: DATE SORTIE | W10: Saisie FSE | X10: FLE (GoOn-Ifra-Ville Bourg-centre social..) | Y10: Declic Emploi HBA | Z10: MIFE 01 | AA10: AIDE FINANCIERE | AB10: Conseillers numériques | AC10: GO ON | AD10: MOBILITE | AE10: ARIANE | AF10: AGENT DE SANTE | AG10: ADAPT | AH10: ORSAC | AI10: REPIT PARENTAL | AJ10: Clauses sociales | AK10: Autres (preciser) | AL10: COMMENTAIRES /OBSERVATION
AL11: Commentaires
A12: 1 | B12: Madame | C12: CHAOU | D12: Bouchra | E12: 35 | F12: Aucun diplômeAmbéreu | H12: 46006 | I12: 46035 | J12: 46035 | K12: =+J12+180 -> 46215 | L12: Renouvellement | M12: SANTE | W12: P1248
A13: 1 | B13: Monsieur | C13: KACZOROWSKI | D13: Gary | E13: 40 | F13: CAP, BEP | G13: Lagnieu | H13: 46007 | I13: 46028 | J13: 46048 | K13: =+J13+180 -> 46228 | M13: MOBILITE | W13: P1250
A14: 0 | B14: Monsieur | C14: PILCH | D14: Jean-Christophe | E14: 47 | F14: BAC PRO | G14: Lagnieu | H14: 46009 | I14: 46028 | J14: 46056 | K14: =+J14+180 -> 46236 | M14: SANTE | N14: MOBILITE | W14: 1 | AF14: 1 | AL14: Mr souhaite repartir en saison pour ne pas rester chez sa mère mais fragilité psy.
A15: 1 | B15: Monsieur | C15: CLOYER | D15: Jérémy | E15: 40 | F15: Aucun diplôme | G15: Ambérieu | H15: 46008 | I15: 46036 | J15: 46036 | K15: =+J15+180 -> 46216 | L15: Renouvellement | M15: SANTE | N15: MOBILITE | O15: LOGEMENT | W15: P1253 | AL15: En attente de réponse de la MDPH pour l'AAH. Relancer/médecin pour CM
A16: 1 | B16: Monsieur | C16: YILMAZ | D16: Mehmet | E16: 50 | F16: Aucun diplôme | G16: Ambérieu | H16: 45995 | I16: 46044 | J16: 46043 | K16: =+J16+180 -> 46223 | M16: Repasser le permis | Q16: , | W16: 1 | AL16: Evenement emploi "ferrovière"pas accepté niveau trop bas
A17: 0 | B17: Monsieur | C17: AL ALI | D17: Abdallah | E17: 41 | F17: Aucun diplôme | G17: Ambérieu | H17: 45811 | I17: 45873 | J17: 45873 | K17: =+J17+180 -> 46053 | M17: LANGUE | N17: SANTE | W17: P249 | AC17: 1 | AL17: analphabètisme en attente de CM -poursuite de GOON jusqu'à juin.
A18: 1 | B18: Madame | C18: ASLIMANI/LAAROUSSI | D18: Nasera | E18: 40 | F18: CAP, BEP | G18: Ambérieu | H18: 45929 | I18: 18/09/20025 | J18: 45968 | K18: =+J18+180 -> 46148 | M18: MOBILITE | N18: SANTE | W18: P1255 | AL18: Très active, participations ateliers jobdating / Animatrice diplôme belge - assistante maternelle agréée
A19: 1 | B19: Madame | C19: BAJRAMOVA | D19: Juksela | E19: 48 | F19: Aucun diplôme | G19: Ambérieu | H19: 45869 | I19: 45911 | J19: 45911 | K19: =+J19+180 -> 46091 | M19: LOGEMENT | N19: SANTE | O19: MOBILITE | P19: 4 | W19: P1246 | AL19: travaille avec STAFFMATCH (petites missions ménage, cuisine) participation atelier, jobdating
A20: 1 | B20: Madame | C20: BERNARDIN | D20: Gaëlle | E20: 43 | F20: Aucun diplôme | G20: Ambérieu | H20: 45812 | I20: 45881 | J20: 45897 | K20: =+J20+180 -> 46077 | L20: Renouvellement | M20: MAMAN SOLO | P20: 3 | W20: P257 | AL20: verifier si bilan envoyé tripartite (doc dep)
A21: 0 | B21: Madame | C21: BORKADI-KHALDI | D21: Cindy | E21: 33 | F21: aucun diplôme | G21: Ambérieu | H21: 45769 | I21: 46260 | J21: 45895 | K21: =+J21+180 -> 46075 | M21: MOBILITE | N21: enfant en situation d'handicap | O21: peu d'expérience professionnelle | P21: 2 | S21: Réorientation | T21: Social freins+ | W21: P435 | AI21: 1 | AL21: Peu disponible - Contrôle régulier de la PMI (1 enfant handicapé - en attente de la PCH) - FAIRE REO SOCIALE CF MAIL
A22: 0 | B22: Monsieur | C22: CLAIRET | D22: Patrice | E22: 43 | F22: Aucun diplôme | G22: Ambérieu | H22: 45820 | I22: 45894 | J22: 45909 | K22: =+J22+180 -> 46089 | M22: SANTE | N22: MOBILITE | S22: Réorientation | T22: Arret mal longue durée | W22: P64 | AL22: CM fourni réo faite le 06/02
A23: 0 | B23: Monsieur | C23: CREPALDI | D23: David | E23: 41 | F23: BAC PRO | G23: Lagnieu | H23: 45821 | I23: 45873 | J23: 45873 | K23: =+J23+180 -> 46053 | M23: SANTE | P23: 2 | Q23: 1 | S23: Réorientation | T23: Arret mal longue durée | W23: P108 | AL23: REO SOCIALE plusieurs hospitalisations
A24: 0 | B24: Monsieur | C24: FARINA | D24: Yann | E24: 42 | F24: Aucun diplôme | G24: Ambérieu | H24: 45814 | I24: 45901 | J24: 45945 | K24: =+J24+180 -> 46125 | M24: sans domicile | N24: frais de déplacement | P24: 3 | S24: Réorientation | T24: Social freins+ | W24: P252 | AL24: incurie
A25: 1 | B25: Madame | C25: FERNANDES | D25: Noemie | E25: 28 | F25: DEUG, BTS, DUT, DEUST | G25: Amberieu | H25: 45814 | I25: 45874 | J25: 45874 | K25: =+J25+180 -> 46054 | L25: Renouvellement | M25: SANTE | N25: Probl perso | P25: 2 | W25: P1249 | AL25: Mme a peur de son ex conjoint - se présente 1 fois sur 2 (remobilisation) ne se mobilise pas
A26: 1 | B26: Madame | C26: FOFANA | D26: Fanta | E26: 29 | F26: aucun diplôme | G26: Ambérieu | H26: 45820 | I26: 45868 | J26: 45912 | K26: =+J26+180 -> 46092 | M26: ECRIT | N26: santé | W26: P111 | AC26: 1 | AL26: Suivi par AGIR- parle tres bien le francais, ne sait pas lire ni ecrire / GO ON A convoquer
A27: 0 | B27: Madame | C27: HAMOT | D27: Whitney | E27: 28 | F27: DEUG, BTS, DUT, DEUST | G27: Lagnieu | H27: 45835 | I27: 45866 | J27: 45873 | K27: =+J27+180 -> 46053 | M27: Enfant bas age | P27: 2 | S27: Réorientation | T27: Social freins+ | W27: P105 | AL27: 4 enfants (3 à l'ecole) - mere celibataire - dernier enfant 18 mois - a été commerciale
A28: 1 | B28: Monsieur | C28: JUVENAL | D28: Cédric | E28: 48 | F28: CAP, BEP | G28: Lagnieu | H28: 45840 | I28: 45901 | J28: 45922 | K28: =+J28+180 -> 46102 | M28: SANTE | P28: 4 | W28: P1254 | AL28: Cdd 3 mois en garage non renouvelé - abs février refixer un rdv sinon REMOB - pas de cv !!
A29: 1 | B29: Madame | C29: KHALO / OMAR | D29: Hanifa | E29: 40 | F29: Aucun diplôme | G29: Ambérieu | H29: 45827 | I29: 45883 | J29: 45912 | K29: =+J29+180 -> 46092 | L29: Renouvellement | M29: LANGUE | N29: SANTE | O29: MOBILITE | W29: P61 | AK29: Léo Lagrange | AL29: CM : le medecin atteste qu elle peut travailler et peut suivre les cours Aintégré Léo Lagrange le 05/03
A30: 0 | B30: Madame | C30: KOUASSI | D30: Amoin Désirée Prudence | E30: 30 | F30: CAP, BEP | G30: Amberieu | H30: 45840 | I30: 45859 | J30: 45859 | K30: =+J30+180 -> 46039 | L30: Renouvellement | M30: SANTE | N30: VEHICULE | P30: 8 | S30: Positive | T30: FT acc pro | U30: SIAE (FT) | W30: P433 | AL30: Très active, PMSMP, achat de véhicule, petits boulots… A démarré LOGIN'S récupérer le contrat et suivre péride d'essai sortie FT
A31: 1 | B31: Madame | C31: LAHURE | D31: Belinda | E31: 47 | F31: Aucun diplôme | G31: Ambérieu | H31: 45832 | I31: 45896 | J31: 45896 | K31: =+J31+180 -> 46076 | L31: Renouvellement | M31: SANTE | N31: Permis en cours | P31: 5 | W31: P462 | AF31: 1 | AL31: Présente PEC pas retenue / petits boulots menage
A32: 1 | B32: Madame | C32: LYONNET | D32: Sandrine | E32: 46 | F32: CAP, BEP | G32: Ambérieu | H32: 45821 | I32: 45882 | J32: 45882 | K32: =+J32+180 -> 46062 | L32: Renouvellement | M32: SANTE | N32: pas de véhicule | P32: 3 | W32: P246 | AL32: en attente de réponse de la MDPH pour l'AAH / voir GPP avec Djamila
A33: 1 | B33: Madame | C33: MAHAMADOU | D33: Haoua | E33: 47 | F33: Aucun diplôme | G33: Ambérieu | H33: 45820 | I33: 45924 | J33: 45938 | K33: =+J33+180 -> 46118 | M33: LANGUE | N33: ISOLEE | O33: SANTE | W33: P245 | AC33: 1 | AL33: Orientée vers cours de français G0 ON - FAIRE REO SOCIALE OU BILAN TRIPARTITE - Personne seule pas de com possible
A34: 0 | B34: Madame | C34: MAHESHE NKUBONAGE | D34: Nicole | E34: 45 | F34: DEUG, BTS, DUT, DEUST | G34: Ambérieu | H34: 45811 | I34: 45902 | J34: 45902 | K34: =+J34+180 -> 46082 | M34: MOBILITE | N34: SANTE | P34: 7 | S34: Réorientation | T34: FT acc pro | V34: 46108 | W34: P464 | AL34: Candidate beaucoup - manque de confiance en soi
A35: 1 | B35: Monsieur | C35: MIGUEL | D35: Herve | E35: 45 | F35: Aucun diplôme | G35: Ambérieu | H35: 45798 | I35: 45873 | J35: 45873 | K35: =+J35+180 -> 46053 | M35: MOBILITE | N35: SANTE | O35: HEBERGEMENT | P35: 1 | AF35: 1 | AL35: voir LOGGINS - CACES a renouveler faire une immersion
A36: 0 | B36: Madame | C36: MOHAMAD | D36: Shirin | E36: 46 | F36: Aucun diplôme | G36: Ambérieu | H36: 45826 | I36: 45883 | J36: 45883 | K36: =+J36+180 -> 46063 | L36: Renouvellement | M36: MOBILITE | N36: SANTE | O36: LANGUE | S36: Réorientation | T36: FT acc pro | V36: 46248 | W36: P107 | AC36: 1 | AD36: 1 | AL36: GO ON, proposition fle/logistique FT2026 : a refusé
A37: 0 | B37: Monsieur | C37: MOTA | D37: Jean Michel | E37: 45 | G37: Lagnieu | H37: 45828 | I37: 45894 | K37: =+J37+180 -> 180 | AL37: Passé en CLI le 12/12/25 - sanctionné à 80% - pas de contact repris
A38: 1 | B38: Monsieur | C38: PIEDBOIS | D38: Youri | E38: 54 | F38: Baccalauréat | G38: Lagnieu | H38: 45821 | I38: 45908 | J38: 45908 | K38: =+J38+180 -> 46088 | L38: Renouvellement | M38: Hebergement | N38: santé | P38: 3 | W38: P566 | AL38: Mr était SDF. Il reprend sa vie en main. Contrat appui entreprise 2 OE proposées refusées
A39: 1 | B39: Monsieur | C39: POTENZIANI | D39: Nicolas | E39: 26 | F39: aucun diplôme | G39: Ambérieu | H39: 45812 | I39: 45887 | J39: 45890 | K39: =+J39+180 -> 46070 | M39: mobilité | N39: peu d'expérience pro | W39: P1262 | AL39: a réussi son code;conduite en cours - Attention Mr ne respecte pas . Prévoir un prochain rdv rapidement si absent REMOB
A40: 1 | B40: Monsieur | C40: PUVILLAN | D40: Cédric | E40: 48 | F40: DEUG, BTS, DUT, DEUST | G40: Amberieu | H40: 45777 | I40: 45866 | J40: 45866 | K40: =+J40+180 -> 46046 | L40: Renouvellement | M40: multiple projet | N40: santé | P40: 1 | W40: P429 | AL40: en interim jusqu'en décembre 2025 - cariste - formation caces 1 b35 ACTUAL - plus de nouvelle
A41: 0 | B41: Madame | C41: RAMDANI | D41: Ikram | E41: 43 | F41: BAC | G41: Lagnieu | H41: 45812 | I41: 45901 | J41: 45901 | K41: =+J41+180 -> 46081 | L41: Renouvellement | M41: maman solo | N41: santé | R41: 1 | S41: Réorientation | T41: FT acco glo | V41: 46266 | W41: P431 | AL41: demarche assistante maternelle ? Pmsmp à faire / aide à domicile / atsem
A42: 1 | B42: Madame | C42: RAMOS | D42: Audrey | E42: 36 | F42: CAP, BEP | G42: Ambérieu | H42: 45827 | I42: 45902 | J42: 45912 | K42: =+J42+180 -> 46092 | L42: Renouvellement | M42: séparation difficile | N42: maman solo | P42: 3 | W42: P106 | AL42: a CAP petite enfance - Chercher un autre projet professionnel
...

Sheet BRSA SORTIES 
A2: Accompagnement des bénéficiaires du RSA - "CIP +" / 2025 | J2: Sortie + sous objectif (les noter en vert tant que vous les garder en suivi dans l'emploi)
A3: Territoire: CDS…. - LOT .../ CLPE ZONE … | J3: suspension remob
A5: Accompagnement des bénéficiaires du RSA - "CIP +" / 2025 | J5: Sortie + sous objectif (les noter en vert tant que vous les garder en suivi dans l'emploi)
A6: Territoire: CDS AMBERIEU/MEXIMIEUX…. - LOT 3.../ CLPE ZONE 3 | J6: suspension remob
A7: Nom de l'OPERATEUR : ALFA3A | J7: Cli
A8: CIP : HELENE VRAINE (arret à partir du 13/3 - arrivée Aviva le | H8: NOMBRE DE BRSA | I8: =+SUM(A12:A241) -> 81 | S8: SORTIES DU DISPOSITIF | X8: Positionnement actions / démarches
J9: DATE | M9: FREINS IDENTIFIES | U9: SORTIES + sous objectif
B10: H/F | C10: NOM | D10: PRENOM | E10: âge | F10: Niveau scolaire | G10: CDS | H10: DATE ORIENTATION | I10: DATE 1ER RDV fixé | J10: C.E SIGNE | K10: FIN CE 6 MOIS | L10: BILAN PARCOURS (7eme mois) | M10: 1 | N10: 2 | O10: autre | P10: NOMBRE D OFFRES D EMPLOI PROPOSEES (OE/INFO COLL/jobdating..) | Q10: NBRE D ENTRETIENS DE RECRUTEMENT OBTENUS SUITE A VOS OFFRES D EMPLOI | R10: PMSMP (1 = oui) | S10: Motif de sortie | T10: MOTIF de la REO | U10: types | V10: DATE SORTIE | W10: Saisie FSE | X10: FLE (GoOn-Ifra-Ville Bourg-centre social..) | Y10: Declic Emploi HBA | Z10: MIFE 01 | AA10: AIDE FINANCIERE | AB10: Conseillers numériques | AC10: GO ON | AD10: MOBILITE | AE10: ARIANE | AF10: AGENT DE SANTE | AG10: ADAPT | AH10: ORSAC | AI10: REPIT PARENTAL | AJ10: Clauses sociales | AK10: Autres (preciser) | AL10: COMMENTAIRES /OBSERVATION
AL11: Commentaires
A12: 1 | B12: Monsieur | C12: AL JOUMAA | D12: Hamoud | E12: 41 | F12: Aucun diplôme | G12: Ambérieu | H12: 45765 | I12: 45896 | K12: =+J12+180 -> 180 | S12: Réorientation | T12: FT acco glo | AL12: Mr AL JOUMAA est venu à son 1er RDV
A13: 1 | B13: Madame | C13: DIVRECHY / COMBEAU | D13: Noémie | E13: 29 | F13: Aucun diplôme | G13: Ambérieu | H13: 45828 | I13: 45894 | K13: =+J13+180 -> 180 | M13: Maman solo | N13: 4 enfants | S13: Fin DD | W13: P27 | AL13: REO BOURG ATTENION sous SDP Mme COMBEAU.Ne dépend plus du cds d'AMBERIEU mais BOURG
A14: 1 | B14: Madame | C14: ELAMBERT | D14: Adeline | E14: 30 | G14: Ambérieu | H14: 45743 | I14: 45869 | K14: =+J14+180 -> 180 | O14: 0 | S14: Réorientation | T14: FT acc pro | AL14: Mme est venue suivie par FT parcours pro
A15: 1 | B15: Madame | C15: ETEMI / ETEMOV | D15: Irmizat | E15: 30 | G15: Ambérieu | H15: 45811 | I15: 45901 | K15: =+J15+180 -> 180 | M15: maman solo | N15: enfant problème de santé | O15: enfant en bas âge | S15: Fin DD | AL15: Logisti+AI99que+AJ103:AQ106
A16: 1 | B16: Madame | C16: GORUR | D16: Andréa | E16: 30 | F16: CAP, BEP | G16: Lagnieu | H16: 45818 | I16: 45894 | K16: =+J16+180 -> 180 | S16: Réorientation | T16: BGE
A17: 1 | B17: Madame | C17: HOUMADI | D17: Mayi | E17: 39 | F17: Aucun diplôme | G17: Ambérieu | H17: 45800 | I17: 45901 | K17: =+J17+180 -> 180 | S17: Déménagement
A18: 1 | B18: Madame | C18: KANGABA-KOKESSE | D18: Michelle | E18: 33 | G18: Ambérieu | H18: 45828 | I18: 45883 | K18: =+J18+180 -> 180 | S18: Fin DD
A19: 1 | B19: Madame | C19: KOKOT | D19: Aude | E19: 36 | G19: Lagnieu | H19: 45819 | I19: 45894 | K19: =+J19+180 -> 180 | S19: Réorientation | T19: BGE
A20: 1 | B20: Monsieur | C20: KRELL | D20: Olivier | E20: 38 | G20: Ambérieu | H20: 45821 | K20: =+J20+180 -> 180 | S20: Réorientation | T20: Sociale AAH
A21: 1 | B21: Madame | C21: KRIACH | D21: Monia | E21: 46 | G21: Ambérieu | H21: 45810 | I21: 45881 | K21: =+J21+180 -> 180 | S21: Déménagement
A22: 1 | B22: Madame | C22: KULA | D22: Gulsun | E22: 40 | G22: Ambérieu | H22: 45758 | I22: 45881 | K22: =+J22+180 -> 180 | S22: Réorientation | T22: FT acc pro | AL22: France T
A23: 1 | B23: Madame | C23: LYONNET | D23: Soulin | E23: 44 | F23: Aucun diplôme | G23: Ambérieu | H23: 45777 | I23: 45889 | K23: =+J23+180 -> 180 | S23: Réorientation | T23: BGE | AL23: A RECONVOQUER
A24: 1 | B24: Monsieur | C24: MACON | D24: Julien | E24: 34 | G24: Lagnieu | H24: 45824 | I24: 45894 | K24: =+J24+180 -> 180 | S24: Réorientation | T24: FT acc pro | U24: FT SIAE
A25: 1 | B25: Madame | C25: MARBACH | D25: Anais | E25: 24 | G25: Ambérieu | H25: 45824 | I25: 45894 | K25: =+J25+180 -> 180 | S25: Déménagement | AL25: Déménagement autre département
A26: 1 | B26: Madame | C26: MARTINEAU | D26: Sandrine | E26: 56 | G26: Lagnieu | H26: 45821 | I26: 45894 | K26: =+J26+180 -> 180 | S26: Réorientation | T26: FT acc pro | U26: FT SIAE
A27: 1 | B27: Madame | C27: MONIER | D27: Lauren | E27: 30 | G27: Lagnieu | H27: 45819 | I27: 45894 | K27: =+J27+180 -> 180 | S27: Réorientation | T27: BGE
A28: 1 | B28: Madame | C28: MOSTEFAOUI | D28: Zaira | E28: 35 | G28: Lagnieu | H28: 45821 | I28: 45894 | K28: =+J28+180 -> 180 | S28: Réorientation | T28: Arret mal longue durée
A29: 1 | B29: Monsieur | C29: MOUSSAOUI | D29: Stéphane | E29: 42 | G29: Lagnieu | H29: 45825 | I29: 45901 | K29: =+J29+180 -> 180 | S29: Réorientation | T29: Arret mal longue durée
A30: 1 | B30: Madame | C30: MUSSARD-PARASKIOVA | D30: Marjorie | E30: 34 | G30: Lagnieu | H30: 45826 | I30: 45901 | K30: =+J30+180 -> 180 | S30: Réorientation | T30: FT acc pro | AL30: CDDde remplacement prolongé
A31: 1 | B31: Madame | C31: PONTANIER | D31: Laura | E31: 36 | F31: Baccalauréat | G31: Ambérieu | H31: 45820 | I31: 45901 | K31: =+J31+180 -> 180 | M31: SANTE | N31: environnement familial | O31: pas de véhicule | S31: Réorientation | T31: Sociale AAH | W31: P24
A32: 1 | B32: Monsieur | C32: RIVET | D32: Leo | E32: 28 | G32: Ambérieu | H32: 45758 | I32: 45910 | K32: =+J32+180 -> 180 | S32: Fin DD | AL32: A eu plusieurs missions intérim. RDV le 15/10
A33: 1 | B33: Madame | C33: ROUGER | D33: Emilie | E33: 28 | G33: Ambérieu | H33: 45777 | I33: 45908 | K33: =+J33+180 -> 180 | S33: Renonciation RSA
A34: 1 | B34: Madame | C34: SECCI | D34: Oceane | E34: 31 | G34: Ambérieu | H34: 45818 | I34: 45908 | K34: =+J34+180 -> 180 | S34: Réorientation | T34: FT acc pro | AL34: SIAE renouvellement L rénoverie
A35: 1 | B35: Madame | C35: SELEM | D35: Fathia | E35: 33 | G35: Lagnieu | H35: 45786 | I35: 45908 | K35: =+J35+180 -> 180 | S35: Réorientation | T35: Sociale maternité
A36: 1 | B36: Madame | C36: SERROUKH | D36: Fatima | E36: 50 | G36: Lagnieu | H36: 45825 | I36: 45901 | K36: =+J36+180 -> 180 | S36: Réorientation | T36: Arret mal longue durée
A37: 1 | B37: Madame | C37: SERVIOLES | D37: Vanessa | E37: 34 | G37: Lagnieu | H37: 45786 | I37: 45908 | K37: =+J37+180 -> 180 | S37: reorientation | T37: acc pro | AL37: Reprise de son emploi en CDI après congé parental
A38: 1 | B38: Madame | C38: TROTOT | D38: Estelle | E38: 28 | G38: Lagnieu | H38: 45821 | I38: 45922 | K38: =+J38+180 -> 180 | M38: SANTE | S38: Réorientation | T38: Arret mal longue durée | AL38: Mme a une réo sociale : certificat médical de son médecin.
A39: 1 | B39: Monsieur | C39: VERNE | D39: Jean-Michel | E39: 32 | G39: Ambérieu | H39: 45821 | I39: 38603 | K39: =+J39+180 -> 180 | S39: Réorientation | T39: Sociale AAH
A40: 1 | B40: Monsieur | C40: VIN | D40: Romain | E40: 36 | G40: Ambérieu | H40: 45748 | I40: 38603 | K40: =+J40+180 -> 180 | S40: Réorientation | T40: FT acco glo | U40: France Travail
A41: 1 | B41: Madame | C41: MOAMMIN | D41: Nadia | E41: 49 | G41: Ambérieu | H41: 45880 | I41: 45916 | K41: =+J41+180 -> 180 | S41: Fin DD
A42: 1 | B42: Madame | C42: SCHEID | D42: Mélanie | E42: 62 | F42: pas de diplôme | G42: Ambérieu | H42: 45881 | I42: 45915 | K42: =+J42+180 -> 180 | S42: Réorientation | T42: Sociale retraite | AL42: J'ai le récépissé de demande de demande de retraite dossier bloqué
...

Sheet Sanctions + absence 
C1: Absence avant signature CE | E1: Absences 2026 cumulées par mois (rdv-atelier-forum-jobdating..) Après signature CE | Q1: Niveau 1 : AVERTISSEMENT AVANT SUSPENSION | W1: Niveau 2 : suspension remobilisation | Z1: Etape 3 : Etape pluridisciplinaire CLI | AA1: 2 eme manquement (process direct etape 3)
A2: Exemple: | C2: 1 | G2: 1 | Q2: 1 | R2: 46084 | S2: 46089 | T2: =S2+15 -> 46104 | U2: 0 | V2: 1 | W2: =T2+35 -> 46139 | X2: 0 | Y2: 1 | Z2: 46147 | AC2: =AB2+35 -> 35
A3: Nom | B3: Prénom | C3: 1ER RDV | D3: 2EME | E3: 1er mois | F3: 2e mois | G3: 3e mois | H3: 4e mois | I3: 5e mois | J3: 6e mois | K3: 7e mois | L3: 8e mois | M3: 9e mois | N3: 10e mois | O3: 11e mois | P3: 12e mois | Q3: Dde etude de situation. | R3: date de la demande | S3: Date courrier CDS (voir extraction transmise) | T3: Délai 15 jours pour contact | U3: Contact BRSA - 15 jours | V3: Mail INFO CDS | W3: Délai de 35 jours pour reprendre contact | X3: le BRSA s'est manifesté ? | Y3: Mail d'info au CDS manifestation ou non dans les 35 jours | Z3: Date CLI si le BRSA ne s'est pas manifesté au bout des 35 jours | AA3: date demande étude de situation (Mail CDS) | AB3: DATE courrier CDS | AC3: 35j pour reprendre contact date butoire | AD3: DATE CLI
A4: =+'AMBERIEU LAGNIEU'!C12 -> CHAOU | B4: =+'AMBERIEU LAGNIEU'!D12 -> Bouchra | T4: =S4+15 -> 15 | W4: =T4+35 -> 50 | AC4: =AB4+35 -> 35
A5: =+'AMBERIEU LAGNIEU'!C13 -> KACZOROWSKI | B5: =+'AMBERIEU LAGNIEU'!D13 -> Gary | C5: 1 | S5: 46225 | T5: =S5+15 -> 46240 | W5: =S5+50 -> 46275 | AC5: =AB5+35 -> 35
A6: =+'AMBERIEU LAGNIEU'!C14 -> PILCH | B6: =+'AMBERIEU LAGNIEU'!D14 -> Jean-Christophe | C6: 1 | T6: =S6+15 -> 15 | W6: =S6+50 -> 50 | AC6: =AB6+35 -> 35
A7: =+'AMBERIEU LAGNIEU'!C15 -> CLOYER | B7: =+'AMBERIEU LAGNIEU'!D15 -> Jérémy | T7: =S7+15 -> 15 | W7: =S7+50 -> 50 | AC7: =AB7+35 -> 35
A8: =+'AMBERIEU LAGNIEU'!C16 -> YILMAZ | B8: =+'AMBERIEU LAGNIEU'!D16 -> Mehmet | C8: 1 | T8: =S8+15 -> 15 | W8: =S8+50 -> 50 | AC8: =AB8+35 -> 35
A9: =+'AMBERIEU LAGNIEU'!C17 -> AL ALI | B9: =+'AMBERIEU LAGNIEU'!D17 -> Abdallah | T9: =S9+15 -> 15 | W9: =S9+50 -> 50 | AC9: =AB9+35 -> 35
A10: =+'AMBERIEU LAGNIEU'!C18 -> ASLIMANI/LAAROUSSI | B10: =+'AMBERIEU LAGNIEU'!D18 -> Nasera | T10: =S10+15 -> 15 | W10: =S10+50 -> 50 | AC10: =AB10+35 -> 35
A11: =+'AMBERIEU LAGNIEU'!C18 -> ASLIMANI/LAAROUSSI | B11: =+'AMBERIEU LAGNIEU'!D18 -> Nasera | T11: =S11+15 -> 15 | W11: =S11+50 -> 50 | AC11: =AB11+35 -> 35
A12: =+'AMBERIEU LAGNIEU'!C19 -> BAJRAMOVA | B12: =+'AMBERIEU LAGNIEU'!D19 -> Juksela | T12: =S12+15 -> 15 | W12: =S12+50 -> 50 | AC12: =AB12+35 -> 35
A13: =+'AMBERIEU LAGNIEU'!C20 -> BERNARDIN | B13: =+'AMBERIEU LAGNIEU'!D20 -> Gaëlle | C13: 1 | T13: =S13+15 -> 15 | W13: =S13+50 -> 50 | AC13: =AB13+35 -> 35
A14: =+'AMBERIEU LAGNIEU'!C21 -> BORKADI-KHALDI | B14: =+'AMBERIEU LAGNIEU'!D21 -> Cindy | T14: =S14+15 -> 15 | W14: =S14+50 -> 50 | AC14: =AB14+35 -> 35
A15: =+'AMBERIEU LAGNIEU'!C22 -> CLAIRET | B15: =+'AMBERIEU LAGNIEU'!D22 -> Patrice | C15: 1 | D15: 1 | T15: =S15+15 -> 15 | W15: =S15+50 -> 50 | AC15: =AB15+35 -> 35
A16: =+'AMBERIEU LAGNIEU'!C23 -> CREPALDI | B16: =+'AMBERIEU LAGNIEU'!D23 -> David | T16: =S16+15 -> 15 | W16: =S16+50 -> 50 | AC16: =AB16+35 -> 35
A17: =+'AMBERIEU LAGNIEU'!C24 -> FARINA | B17: =+'AMBERIEU LAGNIEU'!D24 -> Yann | C17: 1 | T17: =S17+15 -> 15 | W17: =S17+50 -> 50 | AC17: =AB17+35 -> 35
A18: =+'AMBERIEU LAGNIEU'!C25 -> FERNANDES | B18: =+'AMBERIEU LAGNIEU'!D25 -> Noemie | T18: =S18+15 -> 15 | W18: =S18+50 -> 50 | AC18: =AB18+35 -> 35
A19: =+'AMBERIEU LAGNIEU'!C26 -> FOFANA | B19: =+'AMBERIEU LAGNIEU'!D26 -> Fanta | C19: 1 | T19: =S19+15 -> 15 | W19: =S19+50 -> 50 | AC19: =AB19+35 -> 35
A20: =+'AMBERIEU LAGNIEU'!C27 -> HAMOT | B20: =+'AMBERIEU LAGNIEU'!D27 -> Whitney | C20: 1 | T20: =S20+15 -> 15 | W20: =S20+50 -> 50 | AC20: =AB20+35 -> 35
A21: =+'AMBERIEU LAGNIEU'!C28 -> JUVENAL | B21: =+'AMBERIEU LAGNIEU'!D28 -> Cédric | C21: 1 | D21: 1 | T21: =S21+15 -> 15 | W21: =S21+50 -> 50 | AC21: =AB21+35 -> 35
A22: =+'AMBERIEU LAGNIEU'!C29 -> KHALO / OMAR | B22: =+'AMBERIEU LAGNIEU'!D29 -> Hanifa | C22: 1 | T22: =S22+15 -> 15 | W22: =S22+50 -> 50 | AC22: =AB22+35 -> 35 | AD22: 46266
A23: =+'AMBERIEU LAGNIEU'!C30 -> KOUASSI | B23: =+'AMBERIEU LAGNIEU'!D30 -> Amoin Désirée Prudence | T23: =S23+15 -> 15 | W23: =S23+50 -> 50 | AC23: =AB23+35 -> 35
A24: =+'AMBERIEU LAGNIEU'!C31 -> LAHURE | B24: =+'AMBERIEU LAGNIEU'!D31 -> Belinda | T24: =S24+15 -> 15 | W24: =S24+50 -> 50 | AC24: =AB24+35 -> 35
A25: =+'AMBERIEU LAGNIEU'!C32 -> LYONNET | B25: =+'AMBERIEU LAGNIEU'!D32 -> Sandrine | T25: =S25+15 -> 15 | W25: =S25+50 -> 50 | AC25: =AB25+35 -> 35
A26: =+'AMBERIEU LAGNIEU'!C33 -> MAHAMADOU | B26: =+'AMBERIEU LAGNIEU'!D33 -> Haoua | C26: 1 | T26: =S26+15 -> 15 | W26: =S26+50 -> 50 | AC26: =AB26+35 -> 35
A27: =+'AMBERIEU LAGNIEU'!C34 -> MAHESHE NKUBONAGE | B27: =+'AMBERIEU LAGNIEU'!D34 -> Nicole | T27: =S27+15 -> 15 | W27: =S27+50 -> 50 | AC27: =AB27+35 -> 35
A28: =+'AMBERIEU LAGNIEU'!C35 -> MIGUEL | B28: =+'AMBERIEU LAGNIEU'!D35 -> Herve | T28: =S28+15 -> 15 | W28: =S28+50 -> 50 | AC28: =AB28+35 -> 35
A29: =+'AMBERIEU LAGNIEU'!C36 -> MOHAMAD | B29: =+'AMBERIEU LAGNIEU'!D36 -> Shirin | T29: =S29+15 -> 15 | W29: =S29+50 -> 50 | AC29: =AB29+35 -> 35
A30: =+'AMBERIEU LAGNIEU'!C37 -> MOTA | B30: =+'AMBERIEU LAGNIEU'!D37 -> Jean Michel | C30: 1 | D30: 1 | T30: =S30+15 -> 15 | W30: =S30+50 -> 50 | AC30: =AB30+35 -> 35
A31: =+'AMBERIEU LAGNIEU'!C38 -> PIEDBOIS | B31: =+'AMBERIEU LAGNIEU'!D38 -> Youri | T31: =S31+15 -> 15 | W31: =S31+50 -> 50 | AC31: =AB31+35 -> 35
A32: =+'AMBERIEU LAGNIEU'!C39 -> POTENZIANI | B32: =+'AMBERIEU LAGNIEU'!D39 -> Nicolas | C32: 1 | T32: =S32+15 -> 15 | W32: =S32+50 -> 50 | AC32: =AB32+35 -> 35
A33: =+'AMBERIEU LAGNIEU'!C40 -> PUVILLAN | B33: =+'AMBERIEU LAGNIEU'!D40 -> Cédric | T33: =S33+15 -> 15 | W33: =S33+50 -> 50 | AC33: =AB33+35 -> 35
A34: =+'AMBERIEU LAGNIEU'!C41 -> RAMDANI | B34: =+'AMBERIEU LAGNIEU'!D41 -> Ikram | T34: =S34+15 -> 15 | W34: =S34+50 -> 50 | AC34: =AB34+35 -> 35
A35: =+'AMBERIEU LAGNIEU'!C42 -> RAMOS | B35: =+'AMBERIEU LAGNIEU'!D42 -> Audrey | T35: =S35+15 -> 15 | W35: =S35+50 -> 50 | AC35: =AB35+35 -> 35
A36: =+'AMBERIEU LAGNIEU'!C43 -> RONGIER | B36: =+'AMBERIEU LAGNIEU'!D43 -> Marine | T36: =S36+15 -> 15 | W36: =S36+50 -> 50 | AC36: =AB36+35 -> 35
A37: =+'AMBERIEU LAGNIEU'!C44 -> ROUSSEL | B37: =+'AMBERIEU LAGNIEU'!D44 -> Joanna | T37: =S37+15 -> 15 | W37: =S37+50 -> 50 | AC37: =AB37+35 -> 35
A38: =+'AMBERIEU LAGNIEU'!C45 -> SANTANA | B38: =+'AMBERIEU LAGNIEU'!D45 -> Alexis | C38: 1 | D38: 1 | T38: =S38+15 -> 15 | W38: =S38+50 -> 50 | AC38: =AB38+35 -> 35
A39: =+'AMBERIEU LAGNIEU'!C46 -> SCHEID | B39: =+'AMBERIEU LAGNIEU'!D46 -> Marie | T39: =S39+15 -> 15 | W39: =S39+50 -> 50 | AC39: =AB39+35 -> 35
A40: =+'AMBERIEU LAGNIEU'!C47 -> SEYE | B40: =+'AMBERIEU LAGNIEU'!D47 -> Mohamed | C40: 1 exc | T40: =S40+15 -> 15 | W40: =S40+50 -> 50 | AC40: =AB40+35 -> 35
...

Sheet bilan de parcours  + démarches
A1: Exemples | C1: 5 | D1: 7 | E1: 9 | F1: 12 | G1: 15 | H1: 15 | I1: Renouvellement | J1: 46084 | K1: 1 | L1: 15 | M1: 15 | N1: 15 | O1: 15 | P1: 15 | Q1: 15 | R1: 46268 | S1: Reo FT
C3: nombres de démarches / par semaine | I3: 7 eme mois Bilan fin de parcours | L3: nombres de démarches / par semaine | R3: 14éme mois Bilan définitif
A4: nom | B4: prenom | C4: 1er mois | D4: 2e mois | E4: 3e mois | F4: 4e mois | G4: 5e mois | H4: 6e mois | I4: demande | J4: Date | K4: Renouvellement | L4: 8e mois | M4: 9e mois | N4: 10e mois | O4: 11e mois | P4: 12e mois | Q4: 13e mois | R4: Date | S4: Préco Réo
A5: =+'AMBERIEU LAGNIEU'!C12 -> CHAOU | B5: =+'AMBERIEU LAGNIEU'!D12 -> Bouchra
A6: =+'AMBERIEU LAGNIEU'!C13 -> KACZOROWSKI | B6: =+'AMBERIEU LAGNIEU'!D13 -> Gary
A7: =+'AMBERIEU LAGNIEU'!C14 -> PILCH | B7: =+'AMBERIEU LAGNIEU'!D14 -> Jean-Christophe
A8: =+'AMBERIEU LAGNIEU'!C15 -> CLOYER | B8: =+'AMBERIEU LAGNIEU'!D15 -> Jérémy
A9: =+'AMBERIEU LAGNIEU'!C16 -> YILMAZ | B9: =+'AMBERIEU LAGNIEU'!D16 -> Mehmet
A10: =+'AMBERIEU LAGNIEU'!C17 -> AL ALI | B10: =+'AMBERIEU LAGNIEU'!D17 -> Abdallah
A11: =+'AMBERIEU LAGNIEU'!#REF! -> #REF! | B11: =+'AMBERIEU LAGNIEU'!#REF! -> #REF!
A12: =+'AMBERIEU LAGNIEU'!C18 -> ASLIMANI/LAAROUSSI | B12: =+'AMBERIEU LAGNIEU'!D18 -> Nasera
A13: =+'AMBERIEU LAGNIEU'!C19 -> BAJRAMOVA | B13: =+'AMBERIEU LAGNIEU'!D19 -> Juksela
A14: =+'AMBERIEU LAGNIEU'!C20 -> BERNARDIN | B14: =+'AMBERIEU LAGNIEU'!D20 -> Gaëlle
A15: =+'AMBERIEU LAGNIEU'!C21 -> BORKADI-KHALDI | B15: =+'AMBERIEU LAGNIEU'!D21 -> Cindy
A16: =+'AMBERIEU LAGNIEU'!C22 -> CLAIRET | B16: =+'AMBERIEU LAGNIEU'!D22 -> Patrice
A17: =+'AMBERIEU LAGNIEU'!C23 -> CREPALDI | B17: =+'AMBERIEU LAGNIEU'!D23 -> David
A18: =+'AMBERIEU LAGNIEU'!C24 -> FARINA | B18: =+'AMBERIEU LAGNIEU'!D24 -> Yann
A19: =+'AMBERIEU LAGNIEU'!C25 -> FERNANDES | B19: =+'AMBERIEU LAGNIEU'!D25 -> Noemie
A20: =+'AMBERIEU LAGNIEU'!C26 -> FOFANA | B20: =+'AMBERIEU LAGNIEU'!D26 -> Fanta
A21: =+'AMBERIEU LAGNIEU'!C27 -> HAMOT | B21: =+'AMBERIEU LAGNIEU'!D27 -> Whitney
A22: =+'AMBERIEU LAGNIEU'!C28 -> JUVENAL | B22: =+'AMBERIEU LAGNIEU'!D28 -> Cédric
A23: =+'AMBERIEU LAGNIEU'!C29 -> KHALO / OMAR | B23: =+'AMBERIEU LAGNIEU'!D29 -> Hanifa
... A55: =+'AMBERIEU LAGNIEU'!C61 -> SLIMANI | B55: =+'AMBERIEU LAGNIEU'!D61 -> Lahouaria
A56: =+'AMBERIEU LAGNIEU'!#REF! -> #REF! | B56: =+'AMBERIEU LAGNIEU'!#REF! -> #REF!
A57: =+'AMBERIEU LAGNIEU'!C62 -> MALIQI | B57: =+'AMBERIEU LAGNIEU'!D62 -> Qendrese
A58: =+'AMBERIEU LAGNIEU'!C63 -> MULLAEVA | B58: =+'AMBERIEU LAGNIEU'!D63 -> Malvina
A59: =+'AMBERIEU LAGNIEU'!#REF! -> #REF! | B59: =+'AMBERIEU LAGNIEU'!#REF! -> #REF!
A60: =+'AMBERIEU LAGNIEU'!C64 -> MICHALET | B60: =+'AMBERIEU LAGNIEU'!D64 -> Jean Louis
A61: =+'AMBERIEU LAGNIEU'!C65 -> LOMBARD | B61: =+'AMBERIEU LAGNIEU'!D65 -> Aurelia
A62: =+'AMBERIEU LAGNIEU'!C66 -> TEKIN | B62: =+'AMBERIEU LAGNIEU'!D66 -> Vural
A63: =+'AMBERIEU LAGNIEU'!C67 -> VANEENOO | B63: =+'AMBERIEU LAGNIEU'!D67 -> Cedric
A64: =+'AMBERIEU LAGNIEU'!C68 -> YOUSEF | B64: =+'AMBERIEU LAGNIEU'!D68 -> Siraj
A65: =+'AMBERIEU LAGNIEU'!C69 -> OLRY | B65: =+'AMBERIEU LAGNIEU'!D69 -> Florence
A66: =+'AMBERIEU LAGNIEU'!#REF! -> #REF! | B66: =+'AMBERIEU LAGNIEU'!#REF! -> #REF!
A67: =+'AMBERIEU LAGNIEU'!C70 -> TURPIN | B67: =+'AMBERIEU LAGNIEU'!D70 -> Océane
A68: =+'AMBERIEU LAGNIEU'!#REF! -> #REF! | B68: =+'AMBERIEU LAGNIEU'!#REF! -> #REF!
A69: =+'AMBERIEU LAGNIEU'!C71 -> CHERON | B69: =+'AMBERIEU LAGNIEU'!D71 -> Carine
A70: =+'AMBERIEU LAGNIEU'!C72 -> BEN BRAHIM | B70: =+'AMBERIEU LAGNIEU'!D72 -> Ridha
A71: =+'AMBERIEU LAGNIEU'!C73 -> MESSAI/RIBEIRO | B71: =+'AMBERIEU LAGNIEU'!D73 -> Hadda
A72: =+'AMBERIEU LAGNIEU'!C74 -> VEUGLE | B72: =+'AMBERIEU LAGNIEU'!D74 -> Alison
...

Sheet Tableau croisé NE PAS TOUCHER
A3: Sanction et Absence | E3: Bilan de parcours + démarches
A4: Nombre de 1ER RDV | B4: 31 | E4: Somme de 1er mois
A5: Somme de 2EME | B5: 7 | E5: Somme de 2e mois
A6: Nombre de 1er mois | E6: Somme de 3e mois
A7: Nombre de 2e mois | E7: Somme de 4e mois
A8: Somme de 3e mois | E8: Somme de 5e mois
A9: Somme de 4e mois | E9: Somme de 6e mois
A10: Somme de 5e mois | B10: 2 | E10: Nombre de demande
A11: Nombre de 6e mois | B11: 3 | E11: Somme de Renouvellement
A12: Nombre de 7e mois | E12: Somme de 8e mois
A13: Nombre de 8e mois | E13: Somme de 9e mois
A14: Nombre de 9e mois | E14: Somme de 10e mois
A15: Nombre de 10e mois | E15: Somme de 11e mois
A16: Nombre de 11e mois | E16: Somme de 12e mois
A17: Nombre de 12e mois | E17: Somme de Préco Réo
A18: Somme de date demande étude de situation (Mail CDS)
A19: Somme de Dde etude de situation. | B19: 1
A21: Valeurs | C21: SEXE | D21: Nombre de H/F | E21: SORTIES | F21: Nombre de Motif de sortie | G21: Nombre de MOTIF de la REO
A22: Moyenne de âge | B22: 39.275449 | C22: Madame | D22: 56 | E22: autre | F22: 1 | G22: 1
A23: Nombre de C.E SIGNE | B23: 110 | C23: Monsieur | D23: 44 | E23: Arret mal longue durée | F23: 1 | G23: 1
A24: Nombre de BILAN PARCOURS (7eme mois) | C24: (vide) | E24: Fin DD | F24: 1
A25: Somme de PMSMP (1 = oui) | C25: Madame | D25: 8 | E25: (vide) | F25: 1
A26: Nombre de H/F | B26: 177 | C26: Mme | D26: 1 | E26: Réorientation | F26: 1 | G26: 1
A27: Nombre de Saisie FSE | B27: 51 | C27: Monsieur | D27: 4 | E27: arrêt longue maladie | F27: 1 | G27: 1
A28: Nombre de AIDE FINANCIERE | C28: Total général | D28: 113 | E28: (vide)
E29: (vide)
E30: reorientation | F30: 1 | G30: 1
A31: SORTIES POSITIVES | B31: Nombre de types | E31: FT acc pro | F31: 1 | G31: 1
A32: (vide) | E32: Total général | F32: 4 | G32: 3
A33: Total général

Sheet liste deroulante
A1: Années après le Bac | B1: Titre du diplôme | C1: Niveau de diplôme | F1: Réorientation | H1: Motifs Sorties | J1: Sorties
B2: Aucun diplôme | F2: Sociale AAH | G2: Emploi | H2: Positive | J2: CDI >ou= 24h
A3: - | B3: CAP, BEP | C3: 3 (anciennement V) | E3: H | F3: Sociale retraite | G3: Formation | H3: Réorientation | J3: CDD +6mois >ou=254h
A4: Bac | B4: Baccalauréat | C4: 4 (anciennement IV) | E4: F | F4: Sociale maternité | G4: Créa entreprise | H4: Déménagement | J4: Créa
A5: Bac+2 | B5: DEUG, BTS, DUT, DEUST | C5: 5 (anciennement III) | F5: Social freins+ | G5: France Travail | H5: Fin DD | J5: Interim>ou= à 970h cumulées / an
A6: Bac+3 | B6: Licence, licence professionnelle | C6: 6 (anciennement II) | F6: Arret mal longue durée | H6: Décès | J6: Stagiaire de la formation
A7: Bac+4 | B7: Maîtrise, master 1 | C7: 6 (anciennement II) | F7: BGE | H7: Renonciation RSA | J7: SIAE (FT)
A8: Bac+5 | B8: Master, diplôme d'études approfondies, diplôme d'études supérieures spécialisées, diplôme d'ingénieur | C8: 7 (anciennement I) | F8: MSA | H8: Incarcération
A9: Bac+8 | B9: Doctorat, habilitation à diriger des recherches | C9: 8 (anciennement I) | F9: FT acc pro | H9: Mauvaise orientation
F10: FT acco glo | H10: Fin bilan parcours
D11: CLI | H11: Radié suite CLI
B12: freins | D12: 1
B13: mobilité | D13: 0
B14: garde enfants
E15: OUI
A16: CDS | B16: Oyonnax | E16: NON | G16: Resultat bilan parcours
B17: Nantua | G17: Réo FT | H17: Reo FT
B18: Belley | G18: Renouvellement | H18: Réo sociale
B19: Valserhone | G19: Tripartite
B20: Pays de Gex | G20: BGE
B21: Croix Blanche
B22: Pierre Goujon
B23: Montrevel
B24: Pont de Vaux
B25: St Didier sur Chalaronne
B26: Trevoux
B27: Chatillon sur Chalaronne
B28: Amberieu
B29: Lagnieu
B30: Miribel

Sheet CODIFICATION ACTIVITE
A3: Besoin
A4: Ordre | B4: Code | C4: Libellé | D4: Libellé | E4: Libellé | F4: Volume horaire Hedbomadaire
A5: 1 | B5: P01 | C5: Choisir un métier | D5: Identification de ses points forts et de ses compétences | E5: Identifier ses points forts et ses compétences | F5: 3
D6: Information sur un métier ou un secteur d'activité | E6: S'informer sur un métier ou un secteur d'activité | F6: 3
D7: Observation en entreprise | E7: Réaliser une observation en entreprise | F7: 3
D8: Enquête métier afin de mieux connaître un métier | E8: Réaliser une enquête métier | F8: 3
D9: Participation à un salon ou un forum pour s'informer sur un métier | E9: Participer à un salon ou un forum pour s'informer sur un métier | F9: 3
A10: 2 | B10: P02 | C10: Se former | D10: Information sur un projet de formation ou de Validation des acquis de l'expérience | E10: S'informer sur un projet de formation ou de validation des acquis de l'expérience | F10: 3
D11: Montage d'un dossier d’inscription à une formation | E11: Monter son dossier de formation | F11: 3
D12: Participation à une formation | E12: Participer à une formation | F12: 35
D13: Participation à un salon ou un forum formation | E13: Participer à un salon ou un forum formation | F13: 3
D14: Initiation à l'informatique ou à Internet | E14: S'initier à l'informatique ou à Internet | F14: 3
D15: Participation à un dispositif d'insertion | E15: Participer à un dispositif d'insertion | F15: 35
A16: 3 | B16: P03 | C16: Préparer sa candidature | D16: Réalisation d'une démarche de VAE | E16: Réaliser une démarche de VAE | F16: 3
D17: Préparation de ses candidatures (CV, lettre de motivation, book) | E17: Réaliser ou mettre à jour son CV sa lettre de motivation ou son portfolio | F17: 3
E18: Développer son réseau | F18: 3
E19: S'inscrire ou compléter son profil sur un réseau professionnel | F19: 3
E20: Réaliser des activités de bénévolat | F20: 5
E21: Organiser ses démarches de recherche d’emploi | F21: 3
E22: Compléter ou publier son profil de compétence | F22: 3
A23: 4 | C23: Trouver un emploi | D23: Recherche d'offres d'emploi ou d'entreprises | E23: Rechercher des offres d'emploi ou d'entreprises | F23: 3
D24: Participation à un salon ou un forum pour rechercher des offres | E24: Participer à un salon ou un forum pour rechercher des offres d'emploi | F24: 3
D25: Réponse à des offres d'emploi | E25: Répondre à des offres d'emploi | F25: 3
D26: Candidatures spontanées | E26: Effectuer des candidatures spontanées | F26: 3
D27: Réalisation du suivi de ses candidatures et relance des recruteurs | E27: Réaliser le suivi de ses candidatures et relancer des recruteurs | F27: 3
D28: Préparation des entretiens d'embauche | E28: Préparer un entretien d'embauche | F28: 3
D29: Réalisation d'entretiens d'embauche | E29: Réaliser un entretien d'embauche | F29: 3
D30: Passation de tests de recrutement (concours, casting…) | E30: Passer des tests de recrutement (concours, casting…) | F30: 3
D31: Réalisation d'une mise en situation professionnelle dans une entreprise | E31: Réaliser une mise en situation professionnelle dans une entreprise | F31: 35
D32: Recherche de missions de service civique | E32: Rechercher des missions de service civique | F32: 3
E33: S'inscrire sur une plateforme de recrutement (agence d'intérim, cabinet de recrutement, site spécialisé…) | F33: 3
A34: 5 | B34: P05 | C34: Ma création et reprise d'entreprise | D34: Recherches pour créer ou reprendre une entreprise | E34: Effectuer des recherches pour créer ou reprendre une entreprise | F34: 3
D35: Réalisation d'une étude de marché auprès de prospects/clients /fournisseurs | E35: Réaliser une étude de marché auprès de prospects/clients /fournisseurs | F35: 3
D36: Participation à un salon ou forum pour s'informer sur la création entreprise | E36: Participer à un salon ou forum pour s'informer sur la création d'entreprise | F36: 3
D37: Réalisation d'un business plan afin de préparer la création de son entreprise | E37: Réaliser un business plan afin de préparer la création de son entreprise | F37: 3
D38: Prise de RDV avec des organismes financiers | E38: Prendre rendez-vous avec des organismes financiers | F38: 3
D39: Réalisation de démarches juridiques de création d'entreprise | E39: Réaliser des démarches juridiques de création d'entreprise | F39: 3
D40: Réalisation d'actions de communication pour faire connaitre son entreprise | E40: Réaliser des actions de communication pour faire connaître son entreprise | F40: 3
D41: Prospection pour développer sa clientèle | E41: Prospecter pour développer sa clientèle | F41: 3
D42: Développement de nouveaux partenariats | E42: Développer de nouveaux partenariats | F42: 3
...

Sheet Feuil1
A1: Nom | B1: Prénom | C1: 1er mois | D1: 2e mois | E1: 3e mois | F1: 4e mois | G1: 5e mois | H1: 6e mois | I1: 7e mois | J1: 8e mois | K1: 9e mois | L1: 10e mois | M1: 11e mois | N1: 12e mois | O1: Dde etude de situation. | P1: date de la demande | Q1: Date courrier CDS (voir extraction transmise) | R1: Délai 15 jours pour contact | S1: Contact BRSA - 15 jours | T1: Mail INFO CDS | U1: Délai de 35 jours pour reprendre contact | V1: le BRSA s'est manifesté ? | W1: Mail d'info au CDS manifestation ou non dans les 35 jours | X1: Date CLI si le BRSA ne s'est pas manifesté au bout des 35 jours | Y1: date demande étude de situation (Mail CDS) | Z1: DATE courrier CDS | AA1: 35j pour reprendre contact date butoire | AB1: DATE CLI
A2: AHAMADA | B2: Fatima | E2: 1 | F2: 1 | O2: 1 | P2: 46052 | Q2: 46057 | R2: 46072 | S2: 0 | T2: 1 | U2: 46107 | Y2: 1 | Z2: 46122 | AA2: 46157
A3: XHAFAJ | B3: IGBALLE | R3: 15 | U3: 50 | AA3: 35
A4: AKKAOUI | B4: Badr | O4: 1 | P4: 46049 | Q4: 46054 | R4: 46069 | U4: 46104 | AA4: 35
A5: ALI ABDULLEH | B5: Maymoun | R5: 15 | U5: 50 | AA5: 35
A6: AMIRAT | B6: Saliha | R6: 15 | U6: 50 | AA6: 35
A7: BA | B7: N Dela | F7: 1 | G7: 1 | O7: 1 | P7: 46049 | Q7: 46054 | R7: 46069 | S7: 1 | T7: 1 | U7: 46104 | AA7: 35
A8: BAKHTOKHIL | B8: Hayatullah | E8: 5 | R8: 15 | U8: 50 | AA8: 35
A9: BAUDHUIN | B9: Claire | G9: 5 | R9: 15 | U9: 50 | AA9: 35
A10: BENOIT GONIN | B10: Lucas | R10: 15 | U10: 50 | AA10: 35
A11: BOUJLOUD | B11: Zeneb | R11: 15 | U11: 50 | AA11: 35
A12: CANI | B12: Rilinda | R12: 15 | U12: 50 | AA12: 35
A13: CELEBI | B13: Bekir | G13: 5 | R13: 15 | U13: 50 | AA13: 35
A14: CERVANTES | B14: Sabrina | R14: 15 | U14: 50 | AA14: 35
A15: CHANAL-MOGUET | B15: Virginie | D15: 5 | R15: 15 | U15: 50 | AA15: 35
A16: CHAUME | B16: Stephanie | R16: 15 | U16: 50 | AA16: 35
A17: DAMIRON | B17: Arthur | O17: 1 | P17: 46049 | Q17: 46054 | R17: 46069 | S17: 1 | T17: 1 | U17: 46104 | AA17: 35
A18: EL ARKOUBI | B18: Touria | R18: 15 | U18: 50 | AA18: 35
A19: EL BAHMANI | B19: Naima | R19: 15 | U19: 50 | AA19: 35
A20: ERASLAN | B20: Eren | O20: 1 | P20: 46049 | Q20: 46054 | R20: 46069 | U20: 46104 | AA20: 35
A21: GILBERT | B21: Stéphanie | R21: 15 | U21: 50 | AA21: 35
A22: HIDA | B22: Soumaya | O22: 1 | P22: 46049 | Q22: 46054 | R22: 46069 | U22: 46104 | AA22: 35
A23: HUMBERT | B23: Jolan | O23: 1 | P23: 46049 | Q23: 46054 | R23: 46069 | U23: 46104 | AA23: 35
A24: KABA | B24: M'balou | R24: 15 | U24: 50 | AA24: 35
A25: KACEM | B25: Houaria | R25: 15 | U25: 50 | AA25: 35
A26: KASEMRATH | B26: Melanie | R26: 15 | U26: 50 | AA26: 35
A27: LAHJAR | B27: Nadia | R27: 15 | U27: 50 | AA27: 35
A28: LAHU | B28: Fabien | R28: 15 | U28: 50 | AA28: 35
A29: LAZRAK | B29: Rajae | R29: 15 | U29: 50 | AA29: 35
A30: MALKI | B30: Hanane | R30: 15 | U30: 50 | AA30: 35
A31: MITKOVA | B31: Marusya | O31: 1 | P31: 46049 | Q31: 46054 | R31: 46069 | S31: 1 | T31: 1 | U31: 46104 | AA31: 35
A32: M'MADI | B32: Zaidine | R32: 15 | U32: 50 | AA32: 35
A33: PATEL | B33: Virginie | R33: 15 | U33: 50 | AA33: 35
A34: ROBERT | B34: Olivier | R34: 15 | U34: 50 | AA34: 35
A35: SIOUDA | B35: Tourkia | R35: 15 | U35: 50 | AA35: 35
A36: SOEUM | B36: Justine | R36: 15 | U36: 50 | AA36: 35
A37: SOUCANE | B37: Pascale | R37: 15 | U37: 50 | AA37: 35
A38: SYED RASHAD | B38: Ayesha | R38: 15 | U38: 50 | AA38: 35
A39: YILMAZ | B39: Talip | R39: 15 | U39: 50 | AA39: 35
A40: AIT YOUSSEF | B40: Maryam | R40: 15 | U40: 50 | AA40: 35
...
