Workbook

Sheet OYONNAX NANTUA
M1: Sortie + sous objectif (les noter en vert tant que vous les garder en suivi dans l'emploi)
B2: Accompagnement des bénéficiaires du RSA - "CIP +" / 2025 | K2: Sortie + sous objectif (les noter en vert tant que vous les garder en suivi dans l'emploi) | M2: suspension remob
B3: Territoire: CDS OYONNAX NANTUA - LOT 2/ CLPE ZONE 4 | K3: suspension remob
B4: Nom de l'OPERATEUR : ALFA3A | K4: Cli
A6: CIP : KIM OU
C7: Somme de BRSA suivi - en cours | D7: =SUM(A13:A543) -> 66 | U7: SORTIES DU DISPOSITIF
U8: SORTIES sous objectif
J9: DATE | M9: DATE | O9: FREINS IDENTIFIES
B11: H/F | C11: NOM | D11: PRENOM | E11: âge | F11: Niveau scolaire | G11: CDS | H11: DATE ORIENTATION | I11: DATE 1ER RDV fixé | J11: CONTRAT ENGAGEMENT SIGNE | K11: FIN ACC | L11: BILAN PARCOURS (7eme mois) | M11: CE Signé | N11: Fin acc 12 mois | O11: 1 | P11: 2 | Q11: autre | R11: NOMBRE D OFFRES D EMPLOI PROPOSEES (OE/INFO COLL/jobdating..)(chiffres à cumuler / mois | S11: NBRE D ENTRETIENS DE RECRUTEMENT OBTENUS SUITE A VOS OFFRES D EMPLOI(chiffres à cumuler / mois | T11: PMSMP | U11: Motif de sortie | V11: MOTIF de la REO | W11: types | X11: DATE SORTIE | Y11: Saisie FSE | Z11: FLE (GoOn-Ifra-Ville Bourg-centre social..) | AA11: Declic Emploi HBA | AB11: MIFE 01 | AC11: AIDE FINANCIERE | AD11: Conseillers numériques | AE11: GO ON | AF11: MOBILITE | AG11: ARIANE | AH11: AGENT DE SANTE | AI11: ADAPT | AJ11: ORSAC | AK11: REPIT PARENTAL | AL11: Clauses sociales | AM11: Autres (preciser) | AN11: COMMENTAIRES /OBSERVATION | AO11: DDE DE CLI
A13: 1 | B13: Monsieur | C13: AL-RIHEMAWEE | D13: Qays | E13: 54 | G13: Oyonnax | H13: 45835 | I13: 45868 | J13: 45930 | K13: =J13+180 -> 46110 | L13: Renouvellement | M13: 46142 | N13: =M13+180 -> 46322 | O13: mobilite | P13: sante mentale | R13: 3 | S13: 2 | Y13: P486 | AE13: 1 | AM13: IAE | AN13: FLE - Défricheur ? Ne va plus au cours de francais / ne parle pas du tout le francais absent atc 12/02 et entretien 13/04
A14: 1 | B14: Monsieur | C14: ARBINOT | D14: Alexandre | E14: 40 | G14: Nantua | H14: 45828 | I14: 45880 | J14: 45880 | K14: =J14+180 -> 46060 | L14: Renouvellement | M14: 46064 | N14: =M14+180 -> 46244 | O14: SANTE | P14: MOBILITE | R14: 0 | T14: 1 | Y14: P121
A15: 1 | B15: Monsieur | C15: CAVDAR | D15: Tugay | E15: 26 | G15: Oyonnax | H15: 45805 | I15: 45894 | J15: 45929 | K15: =J15+180 -> 46109 | N15: =M15+180 -> 180 | O15: SANTE | P15: MOBILITE | Y15: P1267 | AN15: absent le02/09 et le 1/10 ATC / pas repris contact Absent 09/06/26 | AO15: 1
A16: 1 | B16: Monsieur | C16: CIMEN | D16: Mehmet | E16: 41 | G16: Oyonnax | H16: 45820 | I16: 45875 | J16: 45896 | K16: =J16+180 -> 46076 | N16: =M16+180 -> 180 | O16: SANTE | P16: MOBILITE | AN16: absences répétes (agent sante et atelier) / Pas repris contact Absent 9/06/26 | AO16: 1
A17: 1 | B17: Madame | C17: DESSAINTJEAN | D17: Amandine | E17: 29 | G17: Nantua | H17: 45771 | I17: 45895 | J17: 45901 | K17: =J17+180 -> 46081 | L17: Renouvellement | M17: 46114 | N17: =M17+180 -> 46294 | O17: mobilité | P17: garde enfant | R17: 6 | S17: 1 | Y17: P93 | AN17: absente le 29/09 - projet ambulanciere
A18: 1 | B18: Monsieur | C18: ERAMIL | D18: Erhan | E18: 38 | G18: Oyonnax | H18: 45770 | I18: 45880 | J18: 45966 | K18: =J18+180 -> 46146 | L18: Renouvellement | M18: 46189 | N18: =M18+180 -> 46369 | R18: 5 | Y18: P232 | AM18: IAE | AN18: absent 11/08 et 28/08 - contact repris pour signer CE - Absent 31/12 ATC //contrôle le 22/04 // absent le 7/05 et ATC 12/05 // absent le 13/07 | AO18: 1
A19: 1 | B19: Monsieur | C19: JUILLARD | D19: Frédéric | E19: 45 | G19: Nantua | H19: 45838 | I19: 45901 | J19: 45890 | K19: =J19+180 -> 46070 | L19: Renouvellement | M19: 46094 | N19: =M19+180 -> 46274 | O19: mobilite | R19: 3 | T19: 1 | Y19: P50 | AN19: aucun projet se bouger sinon suspension remob
A20: 1 | B20: Madame | C20: KANBOUI | D20: Zineb | E20: 36 | G20: Oyonnax | H20: 45770 | I20: 45889 | J20: 45916 | K20: =J20+180 -> 46096 | L20: Renouvellement | M20: 46122 | N20: =M20+180 -> 46302 | O20: GARDE ENFANTS | P20: fle | Q20: mobilite | R20: 5 | Y20: P72 | AN20: prend cours de francais
A21: 1 | B21: Madame | C21: KONMAZ | D21: Ayse | E21: 51 | G21: Oyonnax | H21: 45845 | I21: 45894 | J21: 45859 | K21: =J21+180 -> 46039 | L21: Renouvellement | M21: 46111 | N21: =M21+180 -> 46291 | O21: mobilité | R21: 7 | S21: 1 | Y21: P113 | AN21: absent ATC 25/09 ET 6/01 ATC 8/01 : SUSPENSION REMOBILISATION | AO21: 1
A22: 1 | B22: Monsieur | C22: LAOUFI | D22: Hamza | E22: 28 | G22: Oyonnax | H22: 45789 | I22: 45894 | J22: 45902 | K22: =J22+180 -> 46082 | L22: Renouvellement | M22: 46163 | N22: =M22+180 -> 46343 | O22: mobilité | R22: 7 | S22: 2 | T22: 1 | Y22: P11 | AN22: CDI DEPUIS 3/03
A23: 1 | B23: Madame | C23: LAMBREZ | D23: Angélique | E23: 44 | G23: Nantua | H23: 45854 | I23: 45925 | J23: 45925 | K23: =J23+180 -> 46105 | L23: Renouvellement | M23: 46125 | N23: =M23+180 -> 46305 | O23: sante | P23: mobilité | R23: 3 | T23: 4 | Y23: P102 | AN23: 3 immersions
A24: 1 | B24: Madame | C24: MOHAMMAD | D24: Sania | E24: 33 | G24: Nantua | H24: 45847 | I24: 45860 | J24: 45880 | K24: =J24+180 -> 46060 | L24: Renouvellement | M24: 46063 | N24: =M24+180 -> 46243 | O24: FLE +++ | P24: MOBILITE | R24: 5 | Y24: P12 | AN24: barriere de la langue - pakistanaise -
A25: 1 | B25: Monsieur | C25: NACIRY | D25: Moussa | E25: 39 | G25: Oyonnax | H25: 45845 | I25: 45859 | J25: 45859 | K25: =J25+180 -> 46039 | L25: Renouvellement | M25: 46113 | N25: =M25+180 -> 46293 | O25: MOBILITE | R25: 1 | S25: 1 | Y25: P978 | AN25: demission poste CDI - absent 12/01 et 15/01 26/01- SUSPENSION REMOB absent ATC 16/03 CDD 2 MOIS
A26: 1 | B26: Madame | C26: OZDEMIR | D26: Songul | E26: 39 | G26: Oyonnax | H26: 45849 | I26: 45915 | J26: 45945 | K26: =J26+180 -> 46125 | L26: Renouvellement | M26: 46132 | N26: =M26+180 -> 46312 | Y26: P737 | AN26: jusqu'en janvier 108h /mois - CDD successifs
A27: 1 | B27: Madame | C27: OZKAN | D27: Nezahat | E27: 50 | G27: Oyonnax | H27: 45835 | I27: 45915 | J27: 45937 | K27: =J27+180 -> 46117 | L27: Renouvellement | M27: 46162 | N27: =M27+180 -> 46342 | O27: fle | R27: 5 | S27: 1 | Y27: P158 | AN27: absent 15/09, petite mission interim
A28: 1 | B28: Madame | C28: OZTURK | D28: Fatma | E28: 40 | G28: Oyonnax | H28: 45820 | I28: 45915 | J28: 45915 | K28: =J28+180 -> 46095 | L28: Renouvellement | M28: 46115 | N28: =M28+180 -> 46295 | O28: garde enfants | R28: 4 | S28: 1 | T28: 1 | Y28: P16 | AM28: iae | AN28: projet ambulanciere
A29: 1 | B29: Monsieur | C29: SAFI | D29: Abdul | E29: 28 | G29: Oyonnax | H29: 45770 | I29: 45901 | J29: 45901 | K29: =J29+180 -> 46081 | L29: Renouvellement | M29: 46132 | N29: =M29+180 -> 46312 | O29: fle | Y29: P1010 | AN29: En emploi interimaire / pbme papier sur SDP impossible d'acceder à son dossier REPRENDRE CONTACT
A30: 1 | B30: Monsieur | C30: SARROUKH | D30: Mohcine | E30: 39 | G30: Oyonnax | H30: 45835 | I30: 45880 | J30: 45973 | K30: =J30+180 -> 46153 | L30: Renouvellement | M30: 46168 | N30: =M30+180 -> 46348 | O30: fle | P30: mobilite | R30: 9 | Y30: P483 | AE30: 1 | AM30: IAE | AN30: absent 9/03
A31: 0 | B31: Madame | C31: TARDY | D31: Anaïs | E31: 36 | G31: Nantua | H31: 45831 | I31: 38603 | J31: 45902 | K31: =J31+180 -> 46082 | L31: Tripartite | N31: =M31+180 -> 180 | O31: garde enfants | P31: mobilite | T31: 1 | Y31: P42 | AN31: absent atc 25/09
A32: 0 | B32: Monsieur | C32: URCEL | D32: Steve | E32: 38 | G32: Oyonnax | H32: 45846 | I32: 45853 | J32: 45996 | K32: =J32+180 -> 46176 | L32: Renouvellement | M32: 46206 | N32: =M32+180 -> 46386 | O32: sante | P32: mobilite | Y32: P316 | AN32: contrat en Espagne qui s'est avéré etre une arnaque - demarches santé - fait des demarches en suisse absent le 05/06 // CDI 13/07/26
A33: 0 | B33: Monsieur | C33: AKAKHIL | D33: Mohammed | E33: 25 | G33: Oyonnax | H33: 45905 | I33: 45930 | J33: 45951 | K33: =J33+180 -> 46131 | L33: Renouvellement | M33: 46104 | N33: =M33+180 -> 46284 | O33: fle +++ | P33: mobilite | R33: 1 | S33: 1 | Y33: P234 | AN33: 600 HEURES OFII Aabsent 30/09 et 4/01 SUSENSION REMOB
A34: 1 | B34: Madame | C34: GUERIAUD | D34: Sabrina | E34: 37 | G34: oyonnax | H34: 45810 | I34: 45929 | J34: 45951 | K34: =J34+180 -> 46131 | L34: Renouvellement | M34: 46134 | N34: =M34+180 -> 46314 | O34: garde enfants | P34: mobilite | R34: 1 | S34: 2 | T34: 1 | Y34: P484 | AN34: Absent 6/01 atc - lui parler du voile… absent atc 10/03 ET 19/05 JOB DATING
A35: 1 | B35: Madame | C35: BELHASSAN | D35: Ilham | E35: 32 | G35: oyonnax | H35: 45936 | I35: 45952 | J35: 45980 | K35: =J35+180 -> 46160 | L35: Renouvellement | M35: 46171 | N35: =M35+180 -> 46351 | O35: garde enfants | R35: 3 | S35: 1 | T35: 1 | Y35: P317 | AM35: IAE
A36: 1 | B36: Madame | C36: LEGGUI | D36: HAFIDA | E36: 34 | G36: Oyonnax | H36: 46013 | I36: 46041 | J36: 46041 | K36: =J36+180 -> 46221 | L36: Renouvellement | M36: 46222 | N36: =M36+180 -> 46402 | O36: GARDE ENFANT | P36: mobilite | T36: 1 | Y36: P766 | AN36: absent 19/01/26 CDD 20/04 AU 31/07
A37: 1 | B37: Monsieur | C37: BENHAMED | D37: ZIED | E37: 47 | G37: Oyonnax | H37: 46029 | I37: 46048 | J37: 46126 | K37: =J37+180 -> 46306 | N37: =M37+180 -> 180 | Y37: P1116 | AN37: Absent 26/01 et 12/03
A38: 0 | B38: Monsieur | C38: SIOUDA | D38: OUSSAMA | E38: 35 | G38: Oyonnax | H38: 46036 | I38: 46050 | J38: 46050 | K38: =J38+180 -> 46230 | N38: =M38+180 -> 180 | R38: 4 | S38: 4 | Y38: P977 | AN38: PAS ACCES SDP Absent 18/02 et 18/05
A39: 1 | B39: Madame | C39: NAOUMI | D39: MILOUDA | E39: 41 | G39: Oyonnax | H39: 46062 | I39: 46080 | J39: 46080 | K39: =J39+180 -> 46260 | N39: =M39+180 -> 180 | O39: garde enfant | P39: mobilite | R39: 2 | S39: 1 | Y39: P1003 | AM39: IAE | AN39: absent atc 10/03
A40: 1 | B40: Monsieur | C40: MORFIN | D40: FREDERIC | E40: 55 | G40: Nantua | H40: 46114 | I40: 46133 | J40: 46133 | K40: =J40+180 -> 46313 | N40: =M40+180 -> 180 | O40: mobilite | R40: 1 | Y40: P1115 | AN40: Absent 10/02 et le 11/03
A41: 1 | B41: Madame | C41: LEBRET | D41: ISABELLE | E41: 53 | G41: Oyonnax | H41: 46090 | I41: 46112 | J41: 46128 | K41: =J41+180 -> 46308 | N41: =M41+180 -> 180 | O41: mobilite | R41: 2 | Y41: P1117
A42: 1 | B42: Madame | C42: COLLOMB | D42: CATHERINE | E42: 61 | G42: Nantua | H42: 46115 | I42: 46133 | J42: 46133 | K42: =J42+180 -> 46313 | N42: =M42+180 -> 180 | R42: 2 | Y42: P1146
A43: 1 | B43: Monsieur | C43: CHAMCHAM | D43: M'barek | E43: 56 | G43: Oyonnax | H43: 46121 | I43: 46140 | J43: 46140 | K43: =J43+180 -> 46320 | N43: =M43+180 -> 180 | O43: langue | R43: 7 | S43: 1 | Y43: P1145 | Z43: 1 | AE43: 1
...

Sheet BRSA Sorties 
B2: Accompagnement des bénéficiaires du RSA - "CIP +" / 2025 | K2: Sortie + sous objectif (les noter en vert tant que vous les garder en suivi dans l'emploi)
B3: Territoire: CDS OYONNAX NANTUA - LOT 2/ CLPE ZONE 4 | K3: suspension remob
B4: Nom de l'OPERATEUR : ALFA3A | K4: Cli
A6: CIP : KIM OU
U7: SORTIES DU DISPOSITIF
C8: Sommes des sorties | D8: =SUM(A13:A602) -> 149 | U8: SORTIES sous objectif
J9: DATE | M9: DATE | O9: FREINS IDENTIFIES
B11: H/F | C11: NOM | D11: PRENOM | E11: âge | F11: Niveau scolaire | G11: CDS | H11: DATE ORIENTATION | I11: DATE 1ER RDV fixé | J11: CONTRAT ENGAGEMENT SIGNE | K11: FIN ACC | L11: BILAN PARCOURS (7eme mois) | M11: CE Signé | N11: Fin acc 12 mois | O11: 1 | P11: 2 | Q11: autre | R11: NOMBRE D OFFRES D EMPLOI PROPOSEES (OE/INFO COLL/jobdating..)(chiffres à cumuler / mois | S11: NBRE D ENTRETIENS DE RECRUTEMENT OBTENUS SUITE A VOS OFFRES D EMPLOI(chiffres à cumuler / mois | T11: PMSMP | U11: Motif de sortie | V11: MOTIF de la REO | W11: types | X11: DATE SORTIE | Y11: Saisie FSE | Z11: FLE (GoOn-Ifra-Ville Bourg-centre social..) | AA11: Declic Emploi HBA | AB11: MIFE 01 | AC11: AIDE FINANCIERE | AD11: Conseillers numériques | AE11: GO ON | AF11: MOBILITE | AG11: ARIANE | AH11: AGENT DE SANTE | AI11: ADAPT | AJ11: ORSAC | AK11: REPIT PARENTAL | AL11: Clauses sociales | AM11: Autres (preciser) | AN11: COMMENTAIRES /OBSERVATION | AO11: DDE DE CLI
A13: 1 | B13: Monsieur | C13: ABID | D13: Mimoun | E13: 62 | G13: Oyonnax | H13: 45835 | I13: 45867 | N13: =M13+180 -> 180 | U13: Réorientation | V13: Sociale retraite
A14: 1 | B14: Monsieur | C14: ALOUANE | D14: Cherif | E14: 42 | G14: Oyonnax | H14: 45812 | I14: 45875 | N14: =M14+180 -> 180 | U14: Réorientation | V14: FT acc pro | X14: 45875 | AN14: parcours accompagnement FT et suivi formation
A15: 1 | B15: Monsieur | C15: BAJRAMOV | D15: Sebastijan | E15: 48 | G15: Oyonnax | H15: 45846 | I15: 45854 | N15: =M15+180 -> 180 | U15: Réorientation | V15: Social freins+ | X15: 45952 | AN15: parti à l'etranger depuis ne s'est jamais inscrit à FT
A16: 1 | B16: Monsieur | C16: BEDOUI | D16: Abdeslam | E16: 74 | G16: Oyonnax | H16: 45846 | I16: 45855 | N16: =M16+180 -> 180 | U16: Réorientation | V16: Sociale retraite | X16: 45862
A17: 1 | B17: Monsieur | C17: BEN MABROUK | D17: Souliman | E17: 35 | G17: Oyonnax | H17: 45819 | I17: 45889 | N17: =M17+180 -> 180 | U17: Réorientation | V17: Arret mal longue durée | X17: 45988
A18: 1 | B18: Monsieur | C18: BEQIRI | D18: Bejta | E18: 76 | G18: Oyonnax | H18: 45846 | I18: 45889 | N18: =M18+180 -> 180 | U18: Réorientation | V18: Sociale retraite | X18: 45866
A19: 1 | B19: Madame | C19: BERTHET-BONDET | D19: Margot | E19: 41 | G19: Nantua | H19: 45804 | I19: 45902 | N19: =M19+180 -> 180 | U19: Réorientation | V19: Social freins+ | X19: 45938
A20: 1 | B20: Monsieur | C20: BORSLA | D20: Tewfik | E20: 63 | G20: Oyonnax | H20: 45831 | I20: 45867 | N20: =M20+180 -> 180 | U20: Réorientation | V20: Social freins+ | X20: 45910 | AN20: certificat medical
A21: 1 | B21: Monsieur | C21: CAVDAR | D21: Ibrahim | E21: 61 | G21: Oyonnax | H21: 45820 | I21: 45894 | J21: 45894 | K21: =J21+180 -> 46074 | N21: =M21+180 -> 180 | U21: Réorientation | V21: Sociale retraite | X21: 45939 | Y21: P771 | AH21: 1
A22: 1 | B22: Monsieur | C22: CEYZERIAT | D22: Samuel | E22: 46 | G22: Nantua | H22: 45770 | I22: 45895 | J22: 45895 | N22: =M22+180 -> 180 | U22: Réorientation | V22: Sociale AAH | X22: 45923 | Y22: P779
A23: 1 | B23: Madame | C23: CHIRON | D23: Aziza | E23: 61 | G23: Oyonnax | H23: 45812 | I23: 45873 | N23: =M23+180 -> 180 | U23: Réorientation | V23: FT acc pro | X23: 45944 | AN23: Absente le 4/8 car en emploi, prochain rdv le 14/10
A24: 1 | B24: Madame | C24: DJELLOUL | D24: Assia | E24: 49 | G24: Oyonnax | H24: 45805 | I24: 45903 | N24: =M24+180 -> 180 | U24: Réorientation | V24: FT acc pro | X24: 45944
A25: 1 | B25: Monsieur | C25: EL AAROUSSI | D25: Chahid | E25: 45 | G25: Oyonnax | H25: 45835 | I25: 45901 | N25: =M25+180 -> 180 | U25: Réorientation | V25: Social freins+ | X25: 45888
A26: 1 | B26: Monsieur | C26: EL KHYAF | D26: Anouar | E26: 39 | G26: Oyonnax | H26: 45835 | I26: 45880 | N26: =M26+180 -> 180 | U26: Réorientation | V26: FT acco glo | X26: 45880
A27: 1 | B27: Monsieur | C27: GUNDUZ | D27: Ibrahim | E27: 48 | G27: Nantua | H27: 45812 | I27: 45901 | N27: =M27+180 -> 180 | U27: Réorientation | V27: BGE | X27: 45897 | AN27: absent 31/07
A28: 1 | B28: Monsieur | C28: JOUINI | D28: Mustapha | E28: 63 | G28: Oyonnax | H28: 45820 | I28: 45901 | N28: =M28+180 -> 180 | U28: Réorientation | V28: Sociale retraite | X28: 45876
A29: 1 | B29: Monsieur | C29: KAMENICA | D29: Ragip | E29: 60 | G29: Oyonnax | H29: 45820 | I29: 45901 | N29: =M29+180 -> 180 | U29: Réorientation | V29: Sociale retraite | X29: 45868
A30: 1 | B30: Monsieur | C30: KANBOUI | D30: Mohammed | E30: 54 | G30: Oyonnax | H30: 45770 | I30: 45868 | N30: =M30+180 -> 180 | U30: Réorientation | V30: FT acco glo | X30: 45868
A31: 1 | B31: Madame | C31: KARAKOC | D31: Ummugulsum | E31: 45 | G31: Nantua | H31: 45770 | I31: 45901 | N31: =M31+180 -> 180 | U31: Renonciation RSA | X31: 45924 | AN31: Absent 01/09
A32: 1 | B32: Monsieur | C32: KHOMSI | D32: Ismaïl | E32: 28 | G32: Oyonnax | H32: 45770 | I32: 45889 | J32: 45919 | U32: Réorientation | V32: FT acc pro | X32: 46100 | AN32: travaille en suisse en interim - infirmier voir si tjrs DD
A33: 1 | B33: Monsieur | C33: MARECAUX | D33: Philippe | E33: 63 | G33: Oyonnax | H33: 45846 | I33: 45901 | U33: Réorientation | V33: Sociale retraite | X33: 45873
A34: 1 | B34: Monsieur | C34: MOUGEL | D34: Jérémy | E34: 30 | G34: Nantua | H34: 45862 | I34: 45901 | J34: 45910 | U34: Renonciation RSA | X34: 45926
A35: 1 | B35: Madame | C35: MURET | D35: Christelle | E35: 50 | G35: Oyonnax | H35: 45835 | I35: 45910 | U35: Réorientation | V35: Arret mal longue durée | X35: 45930
A36: 1 | B36: Monsieur | C36: NAELS | D36: Florian | E36: 36 | G36: Oyonnax | H36: 45821 | I36: 45901 | J36: 45881 | U36: Réorientation | V36: Social freins+ | X36: 46098 | Y36: P123
A37: 1 | B37: Madame | C37: NICOUD | D37: Laetitia | E37: 42 | G37: Oyonnax | H37: 45818 | I37: 45910 | J37: 45910 | U37: Réorientation | V37: Social freins+ | X37: 45944 | Y37: P43
A38: 1 | B38: Monsieur | C38: OZPINAR | D38: Ali | E38: 51 | G38: Oyonnax | H38: 45821 | I38: 45873 | U38: Réorientation | V38: FT acc pro | X38: 45919
A39: 1 | B39: Monsieur | C39: PISANI | D39: Sébastien | E39: 42 | G39: Oyonnax | H39: 45835 | I39: 45874 | U39: Réorientation | V39: Social freins+ | X39: 45902 | AN39: Beneficie de PCH
A40: 1 | B40: Madame | C40: PRAK | D40: Chantha | E40: 58 | G40: Oyonnax | H40: 45848 | I40: 45862 | U40: Réorientation | V40: FT acc pro | X40: 45891
A41: 1 | B41: Monsieur | C41: REGHIOUA | D41: Azzouz | E41: 65 | G41: Oyonnax | H41: 45820 | I41: 45866 | U41: Réorientation | V41: BGE | X41: 45868
A42: 1 | B42: Madame | C42: SYLLA | D42: Ardita | E42: 39 | G42: Oyonnax | H42: 45776 | I42: 38603 | U42: Réorientation | V42: FT acc pro | X42: 45947
A43: 1 | B43: Madame | C43: ERDOGAN /TEMEL | D43: Zeynep | E43: 45 | G43: Nantua | H43: 45831 | I43: 38604 | U43: Réorientation | V43: Sociale AAH | X43: 45952 | Y43: P488
A44: 1 | B44: Madame | C44: UGUZ | D44: Leyla | E44: 43 | G44: Nantua | H44: 45769 | I44: 45889 | U44: Réorientation | V44: FT acc pro | X44: 45889
...

Sheet Sanctions + Absences
C1: Absence avant signature CE | E1: Absences 2026 cumulées par mois (rdv-atelier-forum-jobdating..) Après signature CE | Q1: Niveau 1 : AVERTISSEMENT AVANT SUSPENSION | W1: Niveau 2 : suspension remobilisation | Z1: Etape 3 : Etape pluridisciplinaire CLI | AA1: 2 eme manquement (process direct etape 3)
A2: Nom | B2: Prénom | C2: 1ER RDV | D2: 2EME | E2: 1er mois | F2: 2e mois | G2: 3e mois | H2: 4e mois | I2: 5e mois | J2: 6e mois | K2: 7e mois | L2: 8e mois | M2: 9e mois | N2: 10e mois | O2: 11e mois | P2: 12e mois | Q2: Dde etude de situation. | R2: date de la demande | S2: Date courrier CDS (voir extraction transmise) | T2: Délai 15 jours pour contact | U2: Contact BRSA - 15 jours | V2: Mail INFO CDS | W2: Délai de 35 jours pour reprendre contact | X2: le BRSA s'est manifesté ? | Y2: Mail d'info au CDS manifestation ou non dans les 35 jours | Z2: Date CLI si le BRSA ne s'est pas manifesté au bout des 35 jours | AA2: date demande étude de situation (Mail CDS) | AB2: DATE courrier CDS | AC2: 35j pour reprendre contact date butoire | AD2: DATE CLI
A3: ='BRSA Sorties '!C154 -> AKHMAL | B3: ='BRSA Sorties '!D154 -> Najat | O3: 1 | T3: =S3+15 -> 15 | W3: =T3+35 -> 50 | AC3: =AB3+35 -> 35
A4: ='OYONNAX NANTUA'!C13 -> AL-RIHEMAWEE | B4: ='OYONNAX NANTUA'!D13 -> Qays | C4: 1 | J4: 1 | L4: 1 | Q4: 1 | R4: 46132 | T4: =S4+15 -> 15 | U4: 1 | V4: 1 | W4: =S4+50 -> 50 | X4: 1 | AC4: =AB4+35 -> 35
A5: ='OYONNAX NANTUA'!C14 -> ARBINOT | B5: ='OYONNAX NANTUA'!D14 -> Alexandre | T5: =S5+15 -> 15 | W5: =S5+50 -> 50 | AC5: =AB5+35 -> 35
A6: ='BRSA Sorties '!C98 -> BASSI | B6: ='BRSA Sorties '!D98 -> Stephanie | D6: 1 | T6: =S6+15 -> 15 | W6: =S6+50 -> 50 | AC6: =AB6+35 -> 35
A7: ='BRSA Sorties '!C132 -> BAYIRTEPE | B7: ='BRSA Sorties '!D132 -> Gulsah | C7: 1 | D7: 1 | T7: =S7+15 -> 15 | W7: =S7+50 -> 50 | AC7: =AB7+35 -> 35
A8: ='BRSA Sorties '!C121 -> BERTHET-BONDET | B8: ='BRSA Sorties '!D121 -> Franck | C8: 1 | D8: 1 | T8: =S8+15 -> 15 | W8: =S8+50 -> 50 | AC8: =AB8+35 -> 35
A9: ='BRSA Sorties '!C97 -> BOSCHMANS | B9: ='BRSA Sorties '!D97 -> Franck | C9: 1 | D9: 1 | T9: =S9+15 -> 15 | W9: =S9+50 -> 50 | AC9: =AB9+35 -> 35
A10: ='BRSA Sorties '!C153 -> BRAHIMI | B10: ='BRSA Sorties '!D153 -> Farida | C10: 1 | F10: 1 | H10: 1 | L10: 1 | Q10: 1 | R10: 46136 | S10: 46141 | T10: =S10+15 -> 46156 | U10: 1 | V10: 1 | W10: =S10+50 -> 46191 | X10: 1 | AC10: =AB10+35 -> 35
A11: ='BRSA Sorties '!C123 -> BRASSART | B11: ='BRSA Sorties '!D123 -> Cindy | C11: 1 | D11: 1 | Q11: 1 | R11: 46066 | S11: 46090 | T11: =S11+15 -> 46105 | W11: =S11+50 -> 46140 | X11: 0 | Z11: 46154 | AC11: =AB11+35 -> 35
A12: ='OYONNAX NANTUA'!C15 -> CAVDAR | B12: ='OYONNAX NANTUA'!D15 -> Tugay | C12: 1 | F12: 1 | L12: 1 | T12: =S12+15 -> 15 | W12: =S12+50 -> 50 | AC12: =AB12+35 -> 35
A13: ='BRSA Sorties '!C84 -> CHHUN | B13: ='BRSA Sorties '!D84 -> Sophanna | T13: =S13+15 -> 15 | W13: =S13+50 -> 50 | AC13: =AB13+35 -> 35
A14: ='OYONNAX NANTUA'!C16 -> CIMEN | B14: ='OYONNAX NANTUA'!D16 -> Mehmet | C14: 1 | E14: 1 | N14: 1 | R14: 46199 | S14: 46211 | T14: =S14+15 -> 46226 | W14: =S14+50 -> 46261 | X14: 1 | Z14: 46273 | AC14: =AB14+35 -> 35
A15: ='BRSA Sorties '!C127 -> COLOMBEL | B15: ='BRSA Sorties '!D127 -> Mickael | C15: 1 | D15: 1 | Q15: 1 | R15: 46059 | S15: 46062 | T15: =S15+15 -> 46077 | W15: =S15+50 -> 46112 | X15: 0 | Z15: 46105 | AC15: =AB15+35 -> 35
A16: ='OYONNAX NANTUA'!C17 -> DESSAINTJEAN | B16: ='OYONNAX NANTUA'!D17 -> Amandine | C16: 1 | T16: =S16+15 -> 15 | W16: =S16+50 -> 50 | AC16: =AB16+35 -> 35
A17: ='BRSA Sorties '!C124 -> DUBOT | B17: ='BRSA Sorties '!D124 -> Sébastien | C17: 1 | D17: 1 | Q17: 1 | R17: 46078 | S17: 46083 | T17: =S17+15 -> 46098 | W17: =S17+50 -> 46133 | X17: 0 | Y17: 1 | Z17: 46154 | AC17: =AB17+35 -> 35
A18: ='BRSA Sorties '!C125 -> EL JABBAR | B18: ='BRSA Sorties '!D125 -> Anass | C18: 1 | D18: 1 | T18: =S18+15 -> 15 | W18: =S18+50 -> 50 | AC18: =AB18+35 -> 35
A19: ='BRSA Sorties '!C113 -> EL-HAMDI | B19: ='BRSA Sorties '!D113 -> Mourad | C19: 1 | D19: 1 | Q19: 1 | R19: 46077 | T19: =S19+15 -> 15 | U19: 0 | W19: =S19+50 -> 50 | Z19: 46133 | AC19: =AB19+35 -> 35
A20: ='OYONNAX NANTUA'!C18 -> ERAMIL | B20: ='OYONNAX NANTUA'!D18 -> Erhan | C20: 1 | D20: 1 | F20: 1 | J20: 2 | M20: 1 | Q20: 1 | R20: 46136 | S20: 46161 | T20: =S20+15 -> 46176 | U20: 1 | V20: 1 | W20: =S20+50 -> 46211 | AA20: 46216 | AC20: =AB20+35 -> 35
A21: ='BRSA Sorties '!C96 -> ERSOY | B21: ='BRSA Sorties '!D96 -> Salih | C21: 1 | T21: =S21+15 -> 15 | W21: =S21+50 -> 50 | AC21: =AB21+35 -> 35
A22: ='BRSA Sorties '!C83 -> EZZARHOUNI | B22: ='BRSA Sorties '!D83 -> Nesrdine | T22: =S22+15 -> 15 | W22: =S22+50 -> 50 | AC22: =AB22+35 -> 35
A23: ='BRSA Sorties '!C155 -> GAYNUTDINOV | B23: ='BRSA Sorties '!D155 -> Rafael | T23: =S23+15 -> 15 | W23: =S23+50 -> 50 | AC23: =AB23+35 -> 35
A24: ='OYONNAX NANTUA'!C19 -> JUILLARD | B24: ='OYONNAX NANTUA'!D19 -> Frédéric | C24: 1 | T24: =S24+15 -> 15 | W24: =S24+50 -> 50 | AC24: =AB24+35 -> 35
A25: ='BRSA Sorties '!C151 -> KAMENICA | B25: ='BRSA Sorties '!D151 -> Ardit | Q25: 1 | R25: 46059 | S25: 46091 | T25: =S25+15 -> 46106 | U25: 1 | W25: =S25+50 -> 46141 | AC25: =AB25+35 -> 35
A26: ='OYONNAX NANTUA'!C20 -> KANBOUI | B26: ='OYONNAX NANTUA'!D20 -> Zineb | T26: =S26+15 -> 15 | W26: =S26+50 -> 50 | AC26: =AB26+35 -> 35
A27: ='BRSA Sorties '!C128 -> KARIAM | B27: ='BRSA Sorties '!D128 -> Omar | C27: 1 | D27: 1 | T27: =S27+15 -> 15 | W27: =S27+50 -> 50 | AC27: =AB27+35 -> 35
A28: ='OYONNAX NANTUA'!C21 -> KONMAZ | B28: ='OYONNAX NANTUA'!D21 -> Ayse | C28: 1 | Q28: 1 | T28: =S28+15 -> 15 | W28: =S28+50 -> 50 | AC28: =AB28+35 -> 35
A29: ='OYONNAX NANTUA'!C22 -> LAOUFI | B29: ='OYONNAX NANTUA'!D22 -> Hamza | T29: =S29+15 -> 15 | W29: =S29+50 -> 50 | AC29: =AB29+35 -> 35
A30: ='BRSA Sorties '!C134 -> LEANG DATH | B30: ='BRSA Sorties '!D134 -> Benoît | T30: =S30+15 -> 15 | W30: =S30+50 -> 50 | AC30: =AB30+35 -> 35
A31: ='BRSA Sorties '!C112 -> LIEU | B31: ='BRSA Sorties '!D112 -> Ophelie-kim | C31: 1 | D31: 1 | Q31: 1 | R31: 46120 | S31: 46122 | T31: =S31+15 -> 46137 | U31: 1 | V31: 1 | W31: =S31+50 -> 46172 | AC31: =AB31+35 -> 35
A32: ='BRSA Sorties '!C131 -> MAADOUR | B32: ='BRSA Sorties '!D131 -> Anas | C32: 1 | D32: 1 | T32: =S32+15 -> 15 | W32: =S32+50 -> 50 | AC32: =AB32+35 -> 35
A33: ='BRSA Sorties '!C107 -> MEHALLEL | B33: ='BRSA Sorties '!D107 -> Salim | T33: =S33+15 -> 15 | W33: =S33+50 -> 50 | AC33: =AB33+35 -> 35
A34: ='OYONNAX NANTUA'!C24 -> MOHAMMAD | B34: ='OYONNAX NANTUA'!D24 -> Sania | C34: 1 | K34: 1 | T34: =S34+15 -> 15 | W34: =S34+50 -> 50 | AC34: =AB34+35 -> 35
A35: ='BRSA Sorties '!C140 -> MUTLU | B35: ='BRSA Sorties '!D140 -> Mualla | K35: 1 | T35: =S35+15 -> 15 | W35: =S35+50 -> 50 | AC35: =AB35+35 -> 35
A36: ='OYONNAX NANTUA'!C25 -> NACIRY | B36: ='OYONNAX NANTUA'!D25 -> Moussa | J36: 2 | L36: 1 | T36: =S36+15 -> 15 | W36: =S36+50 -> 50 | AC36: =AB36+35 -> 35
A37: ='BRSA Sorties '!C136 -> OULAKBIR | B37: ='BRSA Sorties '!D136 -> Touria | F37: 1 | T37: =S37+15 -> 15 | W37: =S37+50 -> 50 | AC37: =AB37+35 -> 35
A38: ='BRSA Sorties '!C90 -> OZCAN | B38: ='BRSA Sorties '!D90 -> Okan | C38: 1 | T38: =S38+15 -> 15 | W38: =S38+50 -> 50 | AC38: =AB38+35 -> 35
A39: ='BRSA Sorties '!C119 -> OZCAN | B39: ='BRSA Sorties '!D119 -> Kamile | T39: =S39+15 -> 15 | W39: =S39+50 -> 50 | AC39: =AB39+35 -> 35
A40: ='OYONNAX NANTUA'!C26 -> OZDEMIR | B40: ='OYONNAX NANTUA'!D26 -> Songul | T40: =S40+15 -> 15 | W40: =S40+50 -> 50 | AC40: =AB40+35 -> 35
...

Sheet Bilan de parcours + démarches
C2: nombres de démarches / par semaine | I2: 7 eme mois Bilan fin de parcours | L2: nombres de démarches / par semaine | R2: 14éme mois Bilan définitif
A3: nom | B3: prenom | C3: 1er mois | D3: 2e mois | E3: 3e mois | F3: 4e mois | G3: 5e mois | H3: 6e mois | I3: demande | J3: Date | K3: Renouvellement | L3: 8e mois | M3: 9e mois | N3: 10e mois | O3: 11e mois | P3: 12e mois | Q3: 13e mois | R3: Date | S3: Préco Réo
A4: ='BRSA Sorties '!C154 -> AKHMAL | B4: ='BRSA Sorties '!D154 -> Najat | I4: Renouvellement | J4: 46101
A5: ='OYONNAX NANTUA'!C13 -> AL-RIHEMAWEE | B5: ='OYONNAX NANTUA'!D13 -> Qays
A6: ='OYONNAX NANTUA'!C14 -> ARBINOT | B6: ='OYONNAX NANTUA'!D14 -> Alexandre | I6: Renouvellement | J6: 46064 | K6: 1
A7: ='BRSA Sorties '!C98 -> BASSI | B7: ='BRSA Sorties '!D98 -> Stephanie
A8: ='BRSA Sorties '!C132 -> BAYIRTEPE | B8: ='BRSA Sorties '!D132 -> Gulsah
A9: ='BRSA Sorties '!C121 -> BERTHET-BONDET | B9: ='BRSA Sorties '!D121 -> Franck
A10: ='BRSA Sorties '!C97 -> BOSCHMANS | B10: ='BRSA Sorties '!D97 -> Franck
A11: ='BRSA Sorties '!C153 -> BRAHIMI | B11: ='BRSA Sorties '!D153 -> Farida
A12: ='BRSA Sorties '!C123 -> BRASSART | B12: ='BRSA Sorties '!D123 -> Cindy
A13: ='OYONNAX NANTUA'!C15 -> CAVDAR | B13: ='OYONNAX NANTUA'!D15 -> Tugay
A14: ='BRSA Sorties '!C84 -> CHHUN | B14: ='BRSA Sorties '!D84 -> Sophanna | I14: Renouvellement | J14: 46090 | K14: 0
A15: ='OYONNAX NANTUA'!C16 -> CIMEN | B15: ='OYONNAX NANTUA'!D16 -> Mehmet
A16: ='OYONNAX NANTUA'!#REF! -> #REF! | B16: ='OYONNAX NANTUA'!#REF! -> #REF!
A17: ='OYONNAX NANTUA'!C17 -> DESSAINTJEAN | B17: ='OYONNAX NANTUA'!D17 -> Amandine | I17: Renouvellement | J17: 46114 | L17: 3
A18: ='BRSA Sorties '!C124 -> DUBOT | B18: ='BRSA Sorties '!D124 -> Sébastien
A19: ='BRSA Sorties '!C125 -> EL JABBAR | B19: ='BRSA Sorties '!D125 -> Anass
A20: ='BRSA Sorties '!C113 -> EL-HAMDI | B20: ='BRSA Sorties '!D113 -> Mourad
A21: ='OYONNAX NANTUA'!C18 -> ERAMIL | B21: ='OYONNAX NANTUA'!D18 -> Erhan
A22: ='BRSA Sorties '!C96 -> ERSOY | B22: ='BRSA Sorties '!D96 -> Salih
A23: ='BRSA Sorties '!C83 -> EZZARHOUNI | B23: ='BRSA Sorties '!D83 -> Nesrdine | I23: Réo FT | J23: 46098
A24: ='BRSA Sorties '!C155 -> GAYNUTDINOV | B24: ='BRSA Sorties '!D155 -> Rafael
A25: ='OYONNAX NANTUA'!C19 -> JUILLARD | B25: ='OYONNAX NANTUA'!D19 -> Frédéric | I25: Renouvellement | J25: 46094 | K25: 1
A26: ='BRSA Sorties '!C151 -> KAMENICA | B26: ='BRSA Sorties '!D151 -> Ardit
A27: ='OYONNAX NANTUA'!C20 -> KANBOUI | B27: ='OYONNAX NANTUA'!D20 -> Zineb | I27: Renouvellement | J27: 46125
A28: ='BRSA Sorties '!C128 -> KARIAM | B28: ='BRSA Sorties '!D128 -> Omar
A29: ='OYONNAX NANTUA'!C21 -> KONMAZ | B29: ='OYONNAX NANTUA'!D21 -> Ayse | I29: Renouvellement | J29: 46125
A30: ='OYONNAX NANTUA'!C22 -> LAOUFI | B30: ='OYONNAX NANTUA'!D22 -> Hamza
A31: ='BRSA Sorties '!C134 -> LEANG DATH | B31: ='BRSA Sorties '!D134 -> Benoît | I31: Renouvellement | J31: 46043 | K31: 1
A32: ='BRSA Sorties '!C112 -> LIEU | B32: ='BRSA Sorties '!D112 -> Ophelie-kim
A33: ='BRSA Sorties '!C131 -> MAADOUR | B33: ='BRSA Sorties '!D131 -> Anas
A34: ='BRSA Sorties '!C107 -> MEHALLEL | B34: ='BRSA Sorties '!D107 -> Salim | I34: Renouvellement | J34: 46076 | K34: 1
A35: ='OYONNAX NANTUA'!C24 -> MOHAMMAD | B35: ='OYONNAX NANTUA'!D24 -> Sania
A36: ='BRSA Sorties '!C140 -> MUTLU | B36: ='BRSA Sorties '!D140 -> Mualla | I36: Renouvellement | J36: 46126
A37: ='OYONNAX NANTUA'!C25 -> NACIRY | B37: ='OYONNAX NANTUA'!D25 -> Moussa | I37: Renouvellement | J37: 46113
A38: ='BRSA Sorties '!C136 -> OULAKBIR | B38: ='BRSA Sorties '!D136 -> Touria | I38: Réo FT | J38: 46169
A39: ='BRSA Sorties '!C90 -> OZCAN | B39: ='BRSA Sorties '!D90 -> Okan
A40: ='BRSA Sorties '!C119 -> OZCAN | B40: ='BRSA Sorties '!D119 -> Kamile
A41: ='OYONNAX NANTUA'!C26 -> OZDEMIR | B41: ='OYONNAX NANTUA'!D26 -> Songul | I41: Renouvellement | J41: 46134
...

Sheet Tableau croisé ne pas toucher 
A1: Valeurs | C1: Étiquettes de lignes | D1: Nombre de H/F
A2: Moyenne de âge | B2: 42.876404 | C2: Madame | D2: 68
A3: Nombre de CONTRAT ENGAGEMENT SIGNE | B3: 112 | C3: Monsieur | D3: 117
A4: Nombre de BILAN PARCOURS (7eme mois) | B4: 23 | C4: (vide)
A5: Somme de PMSMP | B5: 25 | C5: Total général | D5: 185
A6: Nombre de H/F | B6: 185
A7: Nombre de Saisie FSE | B7: 85
A8: Nombre de AIDE FINANCIERE
E10: Étiquettes de lignes | F10: Nombre de types
E11: France Travail | F11: 8
E12: FT SIAE | F12: 2
E13: (vide)
E14: CDI >ou= 24h | F14: 1
E15: Créa | F15: 2
E16: Stagiaire en formation | F16: 2
E17: Total général | F17: 15
E19: Bilan de parcours + démarches
E20: Nombre de 1er mois
E21: Nombre de 2e mois
E22: Nombre de 3e mois
E23: Nombre de 4e mois | F23: 1
E24: Nombre de 5e mois
E25: Nombre de 6e mois | F25: 2
E26: Nombre de demande | F26: 23
E27: Nombre de Renouvellement | F27: 5
E28: Nombre de 8e mois | F28: 1
E29: Nombre de 9e mois
E30: Nombre de 11e mois
E31: Nombre de 10e mois
A32: Valeurs | E32: Nombre de 12e mois
A33: Somme de 1ER RDV | B33: 54 | E33: Nombre de Préco Réo
A34: Somme de 2EME | B34: 28
A35: Nombre de 1er mois | B35: 4
A36: Nombre de 2e mois | B36: 6
A37: Nombre de 3e mois | B37: 5 | D37: Étiquettes de lignes | E37: Nombre de MOTIF de la REO | F37: Nombre de Motif de sortie
A38: Nombre de 4e mois | B38: 5 | D38: autre | E38: 1 | F38: 25
A39: Nombre de 5e mois | B39: 1 | D39: Social freins+ | E39: 1 | F39: 1
A40: Nombre de 6e mois | B40: 6 | D40: (vide) | F40: 24
A41: Nombre de 7e mois | B41: 2 | D41: Déménagement | F41: 1
A42: Nombre de 8e mois | B42: 5 | D42: (vide) | F42: 1
...

Sheet liste deroulante
A1: Années après le Bac | B1: Titre du diplôme | C1: Niveau de diplôme | F1: Réorientation | H1: Sorties | J1: Sorties
B2: Aucun diplôme | F2: Sociale AAH | G2: Emploi | H2: Positive | J2: CDI >ou= 24h
A3: - | B3: CAP, BEP | C3: 3 (anciennement V) | E3: H | F3: Sociale retraite | G3: Formation | H3: Réorientation | J3: CDD +6mois >ou=254h
A4: Bac | B4: Baccalauréat | C4: 4 (anciennement IV) | E4: F | F4: Sociale maternité | G4: Créa entreprise | H4: Déménagement | J4: Créa
A5: Bac+2 | B5: DEUG, BTS, DUT, DEUST | C5: 5 (anciennement III) | F5: Social freins+ | G5: France Travail | H5: Fin DD | J5: Interim>ou= à 970h cumulées / an
A6: Bac+3 | B6: Licence, licence professionnelle | C6: 6 (anciennement II) | F6: Arret mal longue durée | H6: autre | J6: Stagiaire en formation
A7: Bac+4 | B7: Maîtrise, master 1 | C7: 6 (anciennement II) | F7: BGE | H7: Renonciation RSA | J7: France Travail
A8: Bac+5 | B8: Master, diplôme d'études approfondies, diplôme d'études supérieures spécialisées, diplôme d'ingénieur | C8: 7 (anciennement I) | F8: MSA | H8: Radié( e ) suite CLI | J8: FT SIAE
A9: Bac+8 | B9: Doctorat, habilitation à diriger des recherches | C9: 8 (anciennement I) | F9: FT acc pro | H9: Mauvaise orientation
F10: FT acco glo | H10: Fin bilan parcours
D11: CLI
B12: freins | D12: 1
B13: mobilité | D13: 0
B14: garde enfants
A16: CDS | B16: Oyonnax | G16: Resultat bilan parcours
B17: Nantua | G17: Réo FT | H17: Reo FT
B18: Belley | G18: Renouvellement | H18: Réo sociale
B19: Valserhone | G19: Tripartite
B20: Pays de Gex | G20: BGE
B21: Croix Blanche
B22: Pierre Goujon
B23: Montrevel
B24: Pont de Vaux
B25: St Didier sur Chalaronne
B26: Trevoux
B27: Chatillon sur Chalaronne
B28: Amberieu
B29: Lagnieu
B30: Miribel

Sheet CODIFICATION ACTIVITE
A3: Besoin
A4: Ordre | B4: Code | C4: Libellé | D4: Libellé | E4: Libellé | F4: Volume horaire Hedbomadaire
A5: 1 | B5: P01 | C5: Choisir un métier | D5: Identification de ses points forts et de ses compétences | E5: Identifier ses points forts et ses compétences | F5: 3
D6: Information sur un métier ou un secteur d'activité | E6: S'informer sur un métier ou un secteur d'activité | F6: 3
D7: Observation en entreprise | E7: Réaliser une observation en entreprise | F7: 3
D8: Enquête métier afin de mieux connaître un métier | E8: Réaliser une enquête métier | F8: 3
D9: Participation à un salon ou un forum pour s'informer sur un métier | E9: Participer à un salon ou un forum pour s'informer sur un métier | F9: 3
A10: 2 | B10: P02 | C10: Se former | D10: Information sur un projet de formation ou de Validation des acquis de l'expérience | E10: S'informer sur un projet de formation ou de validation des acquis de l'expérience | F10: 3
D11: Montage d'un dossier d’inscription à une formation | E11: Monter son dossier de formation | F11: 3
D12: Participation à une formation | E12: Participer à une formation | F12: 35
D13: Participation à un salon ou un forum formation | E13: Participer à un salon ou un forum formation | F13: 3
D14: Initiation à l'informatique ou à Internet | E14: S'initier à l'informatique ou à Internet | F14: 3
D15: Participation à un dispositif d'insertion | E15: Participer à un dispositif d'insertion | F15: 35
A16: 3 | B16: P03 | C16: Préparer sa candidature | D16: Réalisation d'une démarche de VAE | E16: Réaliser une démarche de VAE | F16: 3
D17: Préparation de ses candidatures (CV, lettre de motivation, book) | E17: Réaliser ou mettre à jour son CV sa lettre de motivation ou son portfolio | F17: 3
E18: Développer son réseau | F18: 3
E19: S'inscrire ou compléter son profil sur un réseau professionnel | F19: 3
E20: Réaliser des activités de bénévolat | F20: 5
E21: Organiser ses démarches de recherche d’emploi | F21: 3
E22: Compléter ou publier son profil de compétence | F22: 3
A23: 4 | C23: Trouver un emploi | D23: Recherche d'offres d'emploi ou d'entreprises | E23: Rechercher des offres d'emploi ou d'entreprises | F23: 3
D24: Participation à un salon ou un forum pour rechercher des offres | E24: Participer à un salon ou un forum pour rechercher des offres d'emploi | F24: 3
D25: Réponse à des offres d'emploi | E25: Répondre à des offres d'emploi | F25: 3
D26: Candidatures spontanées | E26: Effectuer des candidatures spontanées | F26: 3
D27: Réalisation du suivi de ses candidatures et relance des recruteurs | E27: Réaliser le suivi de ses candidatures et relancer des recruteurs | F27: 3
D28: Préparation des entretiens d'embauche | E28: Préparer un entretien d'embauche | F28: 3
D29: Réalisation d'entretiens d'embauche | E29: Réaliser un entretien d'embauche | F29: 3
D30: Passation de tests de recrutement (concours, casting…) | E30: Passer des tests de recrutement (concours, casting…) | F30: 3
D31: Réalisation d'une mise en situation professionnelle dans une entreprise | E31: Réaliser une mise en situation professionnelle dans une entreprise | F31: 35
D32: Recherche de missions de service civique | E32: Rechercher des missions de service civique | F32: 3
E33: S'inscrire sur une plateforme de recrutement (agence d'intérim, cabinet de recrutement, site spécialisé…) | F33: 3
A34: 5 | B34: P05 | C34: Ma création et reprise d'entreprise | D34: Recherches pour créer ou reprendre une entreprise | E34: Effectuer des recherches pour créer ou reprendre une entreprise | F34: 3
D35: Réalisation d'une étude de marché auprès de prospects/clients /fournisseurs | E35: Réaliser une étude de marché auprès de prospects/clients /fournisseurs | F35: 3
D36: Participation à un salon ou forum pour s'informer sur la création entreprise | E36: Participer à un salon ou forum pour s'informer sur la création d'entreprise | F36: 3
D37: Réalisation d'un business plan afin de préparer la création de son entreprise | E37: Réaliser un business plan afin de préparer la création de son entreprise | F37: 3
D38: Prise de RDV avec des organismes financiers | E38: Prendre rendez-vous avec des organismes financiers | F38: 3
D39: Réalisation de démarches juridiques de création d'entreprise | E39: Réaliser des démarches juridiques de création d'entreprise | F39: 3
D40: Réalisation d'actions de communication pour faire connaitre son entreprise | E40: Réaliser des actions de communication pour faire connaître son entreprise | F40: 3
D41: Prospection pour développer sa clientèle | E41: Prospecter pour développer sa clientèle | F41: 3
D42: Développement de nouveaux partenariats | E42: Développer de nouveaux partenariats | F42: 3
...

Sheet SANCTION RM
A1: SANCTION REMOBILISATION
J3: DATE premier SM | K3: reven
A4: 0 | B4: Monsieur | C4: OZCAN | D4: Okan | E4: 34403 | F4: 31 | I4: Oyonnax | J4: 46051
A5: 0 | B5: Monsieur | C5: COLOMBEL | D5: Mickael | E5: 31887 | F5: 38 | I5: Oyonnax | J5: 46051
A6: 0 | B6: Madame | C6: OZDEMIR | D6: Emine | E6: 28524 | F6: 47 | I6: Oyonnax | J6: 46052
A7: 0 | B7: Madame | C7: KONMAZ | D7: Ayse | E7: 27108 | F7: 51 | I7: Oyonnax | J7: 46052
A8: 1 | B8: Monsieur | C8: KAMENICA | D8: Ardit | E8: 36678 | F8: 25 | I8: Oyonnax | J8: 46052
A9: 0 | B9: Monsieur | C9: CLERMONT | D9: CHRISTIAN | E9: 25963 | F9: 54 | I9: Nantua | J9: 46052
A10: 1 | B10: Monsieur | C10: GELAJ | D10: Bekim | E10: 33445 | F10: 34 | I10: oyonnax | J10: 46052
A11: 0 | B11: Monsieur | C11: POURCHOUX | D11: GUILLAUME | E11: 28416 | F11: 48 | G11: non soumis D&D depuis Oct 2025 | I11: Oyonnax | J11: 46052
A12: 0 | B12: Monsieur | C12: NEUVILLE | D12: ALLAN | E12: 33079 | F12: 35 | I12: Nantua | J12: 46052
A13: 0 | B13: Madame | C13: ONCU | D13: ONDER | E13: 32076 | F13: 38 | I13: Nantua | J13: 46052
A14: 0 | B14: Monsieur | C14: AKAKHIL | D14: Mohammed | E14: 36526 | F14: 25 | I14: Oyonnax | J14: 46059
A15: 1 | B15: Monsieur | C15: NACIRY | D15: Moussa | E15: 31510 | F15: 39 | I15: Oyonnax | J15: 46059
A16: 0 | B16: Monsieur | C16: ROSELL | D16: Thibault | E16: 30824 | F16: 41 | I16: Oyonnax | J16: 46059
A17: 0 | B17: Monsieur | C17: TEKELI | D17: Atilyahan | E17: 29674 | F17: 44 | I17: oyonnax | J17: 46059
A18: 0 | B18: Monsieur | C18: SULTANKHEL | D18: SAMIULLAH | I18: Oyonnax | J18: 46062
A19: 0 | B19: Madame | C19: NUNES GOUVEIA | D19: SABRINA | E19: 32367 | F19: 37 | I19: Oyonnax | J19: 46066
A20: 0 | B20: Madame | C20: BRASSART | D20: Cindy | E20: 34397 | F20: 31 | I20: Nantua | J20: 46070
A21: 0 | B21: Monsieur | C21: ONCUL | D21: Samet | E21: 34076 | F21: 32 | I21: Oyonnax | J21: 46070
A22: 0 | B22: Monsieur | C22: DERRIEN | D22: BRYCE | E22: 33082 | F22: 35 | I22: Oyonnax | J22: 46073
A23: 0 | B23: Monsieur | C23: TOURNERY | D23: PIERRE-LOU | E23: 36014 | F23: 27 | I23: Nantua | J23: 46077
A24: 0 | B24: Monsieur | C24: EL-HAMDI | D24: Mourad | E24: 30088 | F24: 43 | I24: Oyonnax | J24: 46080
A25: 0 | B25: Monsieur | C25: CHERIFI | D25: HAMZA | E25: 28/11/1993 | F25: 32 | I25: Oyonnax | J25: 46078
A26: 0 | B26: Monsieur | C26: DUBOT | D26: Sébastien | E26: 27167 | F26: 51 | I26: Nantua
A28: =SUM(A26) -> 0
