Workbook

Sheet CROIX BLANCHE PG
A2: Accompagnement des bénéficiaires du RSA - "CIP +" / 2025 | J2: Sortie + sous objectif (les noter en vert tant que vous les garder en suivi dans l'emploi)
A3: Territoire: CDS…. - LOT .../ CLPE ZONE 1 | J3: suspension remob
A4: Nom de l'OPERATEUR : ALFA3A | J4: Cli
A5: CIP : SOILIE TISSERAND | C5: Nombre de BRSA | D5: =+SUM(A9:A457) -> 92 | U5: SORTIES DU DISPOSITIF | Z5: Positionnement actions / démarches
J6: DATE | M6: DATE | O6: FREINS IDENTIFIES | W6: SORTIES + sous objectif
B7: H/F | C7: NOM | D7: PRENOM | E7: âge | F7: Niveau scolaire | G7: CDS | H7: DATE ORIENTATION | I7: DATE 1ER RDV fixé | J7: C.E SIGNE | K7: FIN CE 6 MOIS | L7: BILAN PARCOURS (7eme mois) | M7: C.E SIGNE | N7: FIN CE 12 MOIS | O7: 1 | P7: 2 | Q7: autre | R7: NOMBRE D OFFRES D EMPLOI PROPOSEES (OE/INFO COLL/jobdating..) | S7: NBRE D ENTRETIENS DE RECRUTEMENT OBTENUS SUITE A VOS OFFRES D EMPLOI | T7: PMSMP (1 = oui) | U7: Motif de sortie | V7: MOTIF de la REO | W7: types | X7: DATE SORTIE | Y7: Saisie FSE | Z7: FLE (GoOn-Ifra-Ville Bourg-centre social..) | AA7: Declic Emploi HBA | AB7: MIFE 01 | AC7: AIDE FINANCIERE | AD7: Conseillers numériques | AE7: GO ON | AF7: MOBILITE | AG7: ARIANE | AH7: AGENT DE SANTE | AI7: ADAPT | AJ7: ORSAC | AK7: REPIT PARENTAL | AL7: Clauses sociales | AM7: Autres (preciser) | AN7: COMMENTAIRES /OBSERVATION
L8: SITUATION | R8: (chiffres à cumuler / mois | S8: (chiffres à cumuler / mois | AN8: Commentaires | AP8: PROJET PRO
A9: 1 | B9: Madame | C9: AHMADI | D9: Diba | E9: 36 | F9: Master, diplôme d'études approfondies, diplôme d'études supérieures spécialisées, diplôme d'ingénieur | G9: Pierre Goujon | H9: 45903 | I9: 45931 | J9: 45931 | K9: =+J9+180 -> 46111 | L9: Renouvellement | M9: 46114 | N9: =M9+180 -> 46294 | O9: Langue | R9: 1 | S9: 1 | Y9: P281 | Z9: 1 | AN9: CE OK / Candidature envoyée le 01/10/25 pour poste couturière chez Tremplin | AP9: SIAE COUTURE | AQ9: AHMADI | AR9: Diba | AS9: rohullahaslamy477@gmail.com
A10: 1 | B10: Madame | C10: ACHBAKOU | D10: Naïma | E10: 46 | F10: Aucun diplôme | G10: Pierre Goujon | H10: 46086 | I10: 46188 | J10: 46188 | K10: =+J10+180 -> 46368 | N10: =M10+180 -> 180 | O10: Langue | P10: Mobilité | AP10: AIDE A DOMICILE
B11: madame | C11: ALI
A12: 1 | B12: Madame | C12: ALVES | D12: Merryl | E12: 26 | F12: CAP, BEP | G12: Croix Blanche | H12: 46197 | I12: 46205 | O12: Permis | AP12: CAP EAPE
A13: 1 | B13: Madame | C13: AMARI | D13: Yamina | E13: 49 | F13: Aucun diplôme | G13: Croix Blanche | H13: 45874 | I13: 45922 | J13: 45951 | K13: =+J13+180 -> 46131 | L13: Renouvellement | M13: 46134 | N13: =M13+180 -> 46314 | O13: Langue | P13: Aidante (époux) | R13: 3 | Y13: P358 | AN13: REO SOCIALE A ENVISAGER | AP13: SERVICES PERISCOLAIRES | AQ13: AMARI | AR13: Yamina | AS13: noredine.amari@outlook.fr
A14: 1 | B14: Madame | C14: ARIFI | D14: Sabrina | E14: 25 | F14: Baccalauréat | G14: Croix Blanche | H14: 45866 | I14: 46049 | J14: 46049 | K14: =+J14+180 -> 46229 | L14: Renouvellement | M14: 46230 | N14: =M14+180 -> 46410 | R14: 3 | Y14: P873 | AN14: Entrée en formation CAP AEPE 21/09/26 ENSEIS | AP14: CAP PETITE ENFANCE | AQ14: ARIFI | AR14: Sabrina | AS14: sabrina_arifi@outlook.fr
A15: 1 | B15: Madame | C15: AROUTUNOVA | D15: Suzanna | E15: 40 | O15: Santé | AP15: REO SOCIALE
A16: 1 | B16: Madame | C16: ATHOUMANI | D16: Marie | E16: 38 | F16: Aucun diplôme | G16: Croix Blanche | H16: 45812 | I16: 45890 | J16: 45890 | K16: =+J16+180 -> 46070 | L16: Renouvellement | M16: 46115 | N16: =M16+180 -> 46295 | O16: Langue | P16: Garde enfant | Q16: Logement | R16: 2 | Y16: P338 | AN16: CE OK / Absence injustifiée RDV 3 mail envoyé le 311025 | AP16: HOTELLERIE AIDE A DOMICILE | AQ16: ATHOUMANI | AR16: Marie | AS16: marie13051987@gmail.com
A17: 1 | B17: Madame | C17: AYACH | D17: Samia | E17: 26 | F17: CAP, BEP | G17: Croix Blanche | H17: 46104 | I17: 46153 | J17: 46153 | K17: =+J17+180 -> 46333 | N17: =M17+180 -> 180 | O17: Santé | Y17: P1159 | AN17: SR si absence 15/09 | AP17: AIDE A DOMICILE
A18: 1 | B18: Monsieur | C18: BA | D18: Saïkou | E18: 33 | F18: CAP, BEP | G18: Croix Blanche | I18: 46261 | O18: Santé | AP18: CHAUFFEUR LIVREUR
A19: 1 | B19: Madame | C19: BACAR | D19: Mariata | E19: 27 | F19: Baccalauréat | G19: Pierre Goujon | H19: 45800 | I19: 45960 | J19: 45960 | K19: =+J19+180 -> 46140 | L19: Renouvellement | M19: 46143 | N19: =M19+180 -> 46323 | O19: Permis | R19: 11 | S19: 2 | Y19: P337 | AB19: 1 | AM19: Cap Rebond | AP19: LOGISTIQUE GRANDE DISTRIBUTION | AQ19: BACAR | AR19: Mariata | AS19: mariata.bcr98@gmail.com
A20: 1 | B20: Madame | C20: BAHAR | D20: Laura | E20: 32 | F20: Aucun diplôme | G20: Croix Blanche | I20: 46050 | J20: 46049 | K20: =+J20+180 -> 46229 | L20: Renouvellement | M20: 46231 | N20: =M20+180 -> 46411 | O20: Santé | R20: 1 | Y20: P871 | AM20: CPA | AN20: REO SOCIALE A ENVISAGER | AO20: PMSMP | AP20: MILIEU CARCERAL | AQ20: BAHAR | AR20: Laura | AS20: bahar-l@hotmail.fr
A21: 1 | B21: Monsieur | C21: BANTADIA | D21: Ulrich | E21: 27 | G21: Pierre Goujon | H21: 46029 | I21: 46049 | J21: 46049 | K21: 46235 | L21: Renouvellement | M21: 46231 | N21: =M21+180 -> 46411 | O21: Permis | Y21: P1404 | AN21: Projet formation TP logistique Aftral 0926 | AP21: LOGISTIQUE | AS21: bandatiaulrich@gmail.com
A22: 1 | B22: Madame | C22: BARRY | D22: Aissatou | E22: 29 | F22: Aucun diplôme | G22: Pierre Goujon | H22: 46183 | I22: 46197 | J22: 46197 | K22: =J22+180 -> 46377 | O22: Enfant bas age | Y22: P1414 | AP22: MENAGE
A23: 1 | B23: Monsieur | C23: BASSUS | D23: Jason | E23: 35 | F23: CAP, BEP | G23: Croix Blanche | H23: 46098 | I23: 46113 | J23: 46113 | K23: =+J23+180 -> 46293 | N23: =M23+180 -> 180 | O23: Mobilité | AP23: INDUSTRIE
A24: 1 | B24: Madame | C24: BEAURY | D24: Virginie | E24: 53 | G24: Croix Blanche | H24: 46090 | I24: 46121 | J24: 46121 | K24: =+J24+180 -> 46301 | N24: =M24+180 -> 180
A25: 1 | B25: Madame | C25: BEKELE | D25: Eteferahu | E25: 55 | F25: Aucun diplôme | G25: Pierre Goujon | H25: 45979 | I25: 45993 | J25: 46009 | K25: =+J25+180 -> 46189 | L25: Tripartite | N25: =M25+180 -> 180 | O25: Langue | P25: Illetrisme | Y25: P778 | Z25: 1 | AM25: Cap Rebond | AN25: CE OK / SIAE | AP25: MENAGE/TRI | AQ25: BEKELE | AR25: Eteferahu
A26: 1 | B26: Madame | C26: BELFASSI | D26: Maria Dolores | E26: 43 | F26: Aucun diplôme | G26: Croix Blanche | H26: 45959 | I26: 45992 | J26: 45992 | K26: =+J26+180 -> 46172 | N26: =M26+180 -> 180 | O26: Santé | P26: Enfant TSA | Q26: Langue | Y26: P777 | AN26: CE OK | AP26: SR si absence 21/04 | AQ26: BELFASSI | AR26: Maria Dolores | AS26: 1981belfassi@gmail.com
A27: 1 | B27: Madame | C27: BENAISSA | D27: Radia | E27: 53 | F27: Aucun diplôme | G27: Croix Blanche | H27: 45940 | I27: 45981 | J27: 45981 | K27: =+J27+180 -> 46161 | L27: Renouvellement | M27: 46163 | N27: =M27+180 -> 46343 | Y27: P348 | AN27: CE OK / Couturière indépendante immatriculée CMA / Projet développement activité | AO27: developp activité / Combien d'heures par semaine ? Entreprise aide à domicile + CESU | AP27: COUTURIERE INDEPENDANTE DEV ACTIVITE | AQ27: BENAISSA | AR27: Rabia | AS27: rabia.benaissa@sfr.fr
A28: 1 | B28: Madame | C28: BENCHENAA | D28: Mansouria | E28: 55 | F28: Aucun diplôme | G28: Croix Blanche | H28: 46086 | I28: 46262 | J28: 46262 | K28: =+J28+180 -> 46442 | O28: Santé | P28: Santé mentale | AN28: REO SOCIALE A ENVISAGER
A29: 1 | B29: Monsieur | C29: BEN EL OUALI | D29: Anouar | E29: 27 | F29: CAP, BEP | G29: Pierre Goujon | H29: 45827 | I29: 46049 | J29: 46049 | K29: =+J29+180 -> 46229 | L29: Renouvellement | M29: 46231 | N29: =M29+180 -> 46411 | O29: Permis | Y29: P997 | AN29: CE OK / Projet formation CAP chaudronnier soudeur | AO29: bracelet permis poids lourd | AP29: INDUSTRIE PREPA COMMANDE | AQ29: BEN EL OUALI | AR29: Anouar | AS29: maroquiii01@icloud.com
A30: 1 | B30: Monsieur | C30: BENMELLOUK BENMOUSSA | D30: Abdelkader | E30: 47 | F30: Aucun diplôme | G30: Croix Blanche | H30: 46097 | I30: 46120 | J30: 46120 | K30: =+J30+180 -> 46300 | N30: =M30+180 -> 180 | S30: 1 | Y30: P1105 | AN30: SR SI ABSENCE 24/07
A31: 1 | B31: Monsieur | C31: BENOIT | D31: Xavier | E31: 36 | F31: Aucun diplôme | G31: Pierre Goujon | H31: 45903 | I31: 45925 | J31: 46050 | K31: =+J31+180 -> 46230 | N31: =M31+180 -> 180 | R31: 2 | Y31: P941 | AN31: CLI / CE OK | AO31: aidant familial chauffeur livreur | AP31: CHAUFFEUR LIVREUR | AQ31: BENOIT | AR31: Xavier | AS31: allessio2022@gmail.com
A32: 1 | B32: Monsieur | C32: BENZEKHROUFA | D32: Abdelghani | E32: 49 | F32: CAP, BEP | G32: Pierre Goujon | H32: 46045 | I32: 46065 | J32: 46065 | K32: =+J32+180 -> 46245 | N32: =M32+180 -> 180 | R32: 1 | AN32: CE OK | AO32: INCARCERATION Soumis D& D voir insertion | AP32: RESTAURATION COLLECTIVE | AQ32: BENZEKHROUFA | AR32: Abdelghani | AS32: audir9299@gmail.com
A33: 1 | B33: Madame | C33: BERGER | D33: Stéphanie | E33: 48 | F33: DEUG, BTS, DUT, DEUST | G33: Croix Blanche | H33: 46105 | I33: 46127 | J33: 46127 | K33: =+J33+180 -> 46307 | N33: =M33+180 -> 180 | Y33: P1179 | AN33: Projet CESU 24h/semaine + presta ent nettoyage de bureau | AO33: CDI 22,75H/S annualisé | AP33: MENAGE
A34: 1 | B34: Madame | C34: BERTHILLOT | D34: Léa | E34: 27 | F34: CAP, BEP | G34: Croix Blanche | H34: 46059 | I34: 46078 | J34: 46078 | K34: =+J34+180 -> 46258 | L34: Renouvellement | M34: 46260 | N34: =M34+180 -> 46440 | O34: Santé | R34: 2 | S34: 1 | Y34: P1020 | AN34: CE OK | AO34: CDD jusqu'à fin 0926 28h/semaine | AP34: AIDE A DOMICILE | AQ34: BERTHILLOT | AR34: Léa | AS34: leacaronath01@hotmail.com
A35: 1 | B35: Monsieur | C35: BIDET | D35: Rodolphe | E35: 27 | F35: Baccalauréat | G35: Pierre Goujon | H35: 46133 | I35: 46163 | J35: 46227 | K35: =+J35+180 -> 46407 | N35: =M35+180 -> 180 | R35: 2 | Y35: P1415 | AN35: Statut intermittent en cours | AP35: INGENIEUR DU SON
A36: 1 | B36: Monsieur | C36: BOUFIM | D36: Fouad | E36: 42 | F36: CAP, BEP | G36: Pierre Goujon | H36: 46141 | I36: 46169 | J36: 46182 | K36: =+J36+180 -> 46362 | N36: =M36+180 -> 180 | O36: Suspension permis | R36: 1 | Y36: P1416 | AP36: SOUDURE | AS36: foueddz0119@gmail.com
A37: 1 | B37: Madame | C37: BOUTAIB | D37: Hafida | E37: 46 | G37: Croix Blanche | H37: 46185 | I37: 46204 | J37: 46204 | K37: =+J37+180 -> 46384 | O37: Langue | AP37: ELS
A38: 1 | B38: Madame | C38: BOUZIANE | D38: Fatima | E38: 44 | F38: Baccalauréat | G38: Croix Blanche | H38: 46230 | I38: 46266 | J38: 46266 | K38: =+J38+180 -> 46446 | R38: 1 | AP38: COMPTABILITE
B39: Monsieur | C39: BOUZIDI | D39: El Houcine | E39: 32 | G39: Croix Blanche
B40: Monsieur | C40: BOUZIT | D40: Oycime | E40: 32 | G40: Croix Blanche
A41: 1 | B41: Madame | C41: BOYRAZ | D41: Merve | E41: 28 | G41: Pierre Goujon | H41: 46086 | I41: 46112 | J41: 46112 | K41: =+J41+180 -> 46292 | N41: =M41+180 -> 180 | Y41: P1076 | AO41: 10h/s CESU | AP41: AIDE A DOMICILE
...

Sheet BRSA SORTIES
A2: Accompagnement des bénéficiaires du RSA - "CIP +" / 2025 | J2: Sortie + sous objectif (les noter en vert tant que vous les garder en suivi dans l'emploi)
A3: Territoire: CDS…. - LOT .../ CLPE ZONE 1 | J3: suspension remob
A4: Nom de l'OPERATEUR : ALFA3A | J4: Cli
A5: CIP : SOILIE TISSERAND | C5: Nombre de BRSA | D5: =+SUM(A9:A312) -> 110 | U5: SORTIES DU DISPOSITIF | Z5: Positionnement actions / démarches
J6: DATE | M6: DATE | O6: FREINS IDENTIFIES | W6: SORTIES + sous objectif
B7: H/F | C7: NOM | D7: PRENOM | E7: âge | F7: Niveau scolaire | G7: CDS | H7: DATE ORIENTATION | I7: DATE 1ER RDV fixé | J7: C.E SIGNE | K7: FIN CE 6 MOIS | L7: BILAN PARCOURS (7eme mois) | M7: C.E SIGNE | N7: FIN CE 12 MOIS | O7: 1 | P7: 2 | Q7: autre | R7: NOMBRE D OFFRES D EMPLOI PROPOSEES (OE/INFO COLL/jobdating..) | S7: NBRE D ENTRETIENS DE RECRUTEMENT OBTENUS SUITE A VOS OFFRES D EMPLOI | T7: PMSMP (1 = oui) | U7: Motif de sortie | V7: MOTIF de la REO | W7: types | X7: DATE SORTIE | Y7: Saisie FSE | Z7: FLE (GoOn-Ifra-Ville Bourg-centre social..) | AA7: Declic Emploi HBA | AB7: MIFE 01 | AC7: AIDE FINANCIERE | AD7: Conseillers numériques | AE7: GO ON | AF7: MOBILITE | AG7: ARIANE | AH7: AGENT DE SANTE | AI7: ADAPT | AJ7: ORSAC | AK7: REPIT PARENTAL | AL7: Clauses sociales | AM7: Autres (preciser) | AN7: COMMENTAIRES /OBSERVATION
L8: SITUATION | R8: (chiffres à cumuler / mois | S8: (chiffres à cumuler / mois | AN8: Commentaires | AP8: PROJET PRO
A9: 1 | B9: Madame | C9: ABATI | D9: Nazmije | E9: 61 | G9: Croix Blanche | H9: 45869 | I9: 45904 | N9: =M9+180 -> 180 | U9: Réorientation | V9: Social freins+ | X9: 45950 | Y9: P343
A10: 1 | B10: Monsieur | C10: ABDOULAYE ISSAKH | D10: Yaya | E10: 40 | G10: Pierre Goujon | H10: 45919 | I10: 45939 | K10: =+J10+180 -> 180 | N10: =M10+180 -> 180 | U10: Radié suite CLI | AN10: CLI - PAS DE RETOUR
A11: 1 | B11: Madame | C11: AIOUAZ | D11: Khadija | E11: 34 | G11: Croix Blanche | H11: 45915 | I11: 45938 | K11: =+J11+180 -> 180 | N11: =M11+180 -> 180 | U11: Réorientation | V11: Social freins+ | X11: 46220 | AN11: CDD petits cdd à voir rapidement / Convocation 25/11/25 / 2ABS justifiées 1ABS injustifiée / Relance le 120226 | AO11: Faire réo sociale si 3 mois d'absence | AQ11: AIOUAZ | AR11: Khadija
A12: 1 | B12: Madame | C12: ALI | D12: Mariama | E12: 32 | G12: Croix Blanche | H12: 45765 | I12: 45883 | N12: =M12+180 -> 180 | U12: Réorientation | V12: Sociale maternité
A13: 1 | B13: Madame | C13: ANTOINAT | D13: Jennifer | E13: 40 | G13: Pierre Goujon | H13: 45846 | I13: 45861 | N13: =M13+180 -> 180 | U13: Réorientation | V13: Social freins+ | X13: 45904
A14: 1 | B14: Madame | C14: ARARI | D14: Jennifer | E14: 39 | G14: Croix Blanche | H14: 45838 | I14: 45876 | N14: =M14+180 -> 180 | U14: Réorientation | V14: Social freins+
A15: 1 | B15: Madame | C15: BAITICHE | D15: Karima | E15: 30 | F15: Aucun diplôme | G15: Croix Blanche | H15: 45849 | I15: 45870 | J15: 45870 | K15: =+J15+180 -> 46050 | L15: Renouvellement | M15: 46055 | N15: =M15+180 -> 46235 | O15: Posture pro | P15: Santé mentale | Q15: Mobilité (utilisation TC) | R15: 2 | U15: Fin bilan parcours | V15: FT acc pro | X15: 46236 | Y15: P144 | AM15: Cap Rebond | AN15: CE OK / SIAE voir entreprise adaptée / Relance envoyée 130226 / SR si absence 270326 | AO15: resto social | AP15: SORTIE FT | AQ15: BAITICHE | AR15: Karima
A16: 1 | B16: Madame | C16: BARA | D16: Assetou | E16: 39 | F16: Aucun diplôme | G16: Pierre Goujon | H16: 46100 | I16: 46114 | J16: 46114 | K16: =+J16+180 -> 46294 | N16: =M16+180 -> 180 | U16: Réorientation | V16: BGE | W16: Créa | X16: 46133 | AP16: CREATION ENTREPRISE ENTRETIEN RESIDENCE
A17: 1 | B17: Monsieur | C17: BARAT | D17: Sayed | E17: 32 | G17: Croix Blanche | H17: 45846 | I17: 45889 | K17: =+J17+180 -> 180 | N17: =M17+180 -> 180 | U17: Radié suite CLI | AN17: CLI - pas repris contact
A18: 1 | B18: Madame | C18: BESSON | D18: Florence | E18: 59 | F18: CAP, BEP | G18: Croix Blanche | H18: 46233 | I18: 46245 | J18: 46245 | K18: =+J18+180 -> 46425 | U18: Positive | V18: BGE | W18: Créa | X18: 46272 | AP18: PROJET ENTREPRISE PRODUITS NETTOYAGE
A19: 1 | B19: Madame | C19: BLANC | D19: Mélissa | E19: 31 | F19: Aucun diplôme | G19: Croix Blanche | H19: 45849 | I19: 45867 | J19: 45867 | K19: =+J19+180 -> 46047 | L19: Renouvellement | M19: 46052 | N19: =M19+180 -> 46232 | U19: Fin DD | V19: FT acc pro | X19: 46223 | Y19: P340 | AN19: CE OK - OK Saisonniere 8 - 9 mois / an - recuperer les contrats | AO19: saisonniere | AP19: Fin DD 01/07/26 | AQ19: BLANC | AR19: Mélissa | AS19: melissa-blanc@live.com
A20: 1 | B20: Monsieur | C20: BONNET | D20: Cédric | E20: 31 | F20: CAP, BEP | G20: Croix Blanche | H20: 45840 | I20: 45859 | J20: 45859 | K20: =+J20+180 -> 46039 | L20: RENOUVELLEMENT | M20: 46044 | N20: =M20+180 -> 46224 | O20: Santé | U20: Fin bilan parcours | V20: FT acco glo | X20: 46225 | Y20: P127 | AH20: 1 | AN20: CE OK / Objectif entreprise adapté | AO20: Adapt | AP20: ESAT | AQ20: BONNET | AR20: Cédric | AS20: xeno6156@gmail.com
A21: 1 | B21: Madame | C21: BOTINAJ | D21: Lule | E21: 63 | F21: Aucun diplôme | G21: Pierre Goujon | H21: 45904 | I21: 45929 | N21: =M21+180 -> 180 | U21: Réorientation | V21: Social freins+ | X21: 45966
A22: 1 | B22: Monsieur | C22: BOUILLOUX | D22: Nikolas | E22: 45 | F22: Licence, licence professionnelle | G22: Croix Blanche | H22: 46006 | I22: 46014 | J22: 46050 | K22: =+J22+180 -> 46230 | N22: =M22+180 -> 180 | R22: 3 | U22: Réorientation | V22: FT acc pro | X22: 46174 | Y22: P874 | AN22: REPRISE DE DROITS ARE JUIN 2026 | AP22: RESTAURATION COMMERCE | AQ22: BOUILLOUX | AR22: Nikolas | AS22: bouilloux.niko@gmail.com
A23: 1 | B23: Madame | C23: BOURASSIN | D23: Gaelle | E23: 45 | G23: Pierre Goujon | H23: 45840 | I23: 45866 | N23: =M23+180 -> 180 | U23: Réorientation | V23: Social freins+ | X23: 45957 | Y23: P772
A24: 1 | B24: Madame | C24: BOUVET | D24: Christina | E24: 49 | F24: Aucun diplôme | G24: Pierre Goujon | H24: 45805 | I24: 45894 | J24: 45988 | K24: =+J24+180 -> 46168 | N24: =M24+180 -> 180 | O24: Santé | P24: Mobilité | U24: Fin DD | V24: FT acc pro | X24: 46082 | Y24: P280 | AN24: CE OK / Candidature Frip'One envoyée le 271125 - en interim depuis decembre
A25: 1 | B25: Madame | C25: BOUVIER | D25: Vanessa | E25: 36 | F25: CAP, BEP | G25: Croix Blanche | H25: 45838 | I25: 45919 | J25: 45968 | K25: =+J25+180 -> 46148 | N25: =M25+180 -> 180 | U25: Positive | W25: CDI >ou= 24h | X25: 46113 | Y25: P355 | AN25: CE OK travaille en ehpad en interim | AO25: SR si absence 090626 | AP25: AIDE SOIGNANTE Jardins de brou | AQ25: BOUVIER | AR25: Vanessa | AS25: vanessa.bouvier@hotmail.fr
A26: 1 | B26: Madame | C26: BRACH | D26: Fatiha | E26: 41 | G26: Croix Blanche | H26: 45825 | I26: 45894 | K26: =+J26+180 -> 180 | N26: =M26+180 -> 180 | U26: Radié suite CLI | AN26: CLI pas de nouvelle
A27: 1 | B27: Madame | C27: BRECANI | D27: Arjana | E27: 48 | F27: Aucun diplôme | G27: Pierre Goujon | H27: 45833 | I27: 45868 | J27: 45868 | K27: =+J27+180 -> 46048 | L27: Renouvellement | M27: 46053 | N27: =M27+180 -> 46233 | O27: Santé | U27: Fin bilan parcours | V27: FT acc pro | X27: 46262 | Y27: P143 | AN27: CE OK / En poste nbre d heures 15h/s (CDD à la semaine - Contrat pérenne à obtenir) / CDI 11/2025 ? | AO27: CDI 11,5h/semaine | AP27: REO SOCIALE / FT selon avis médical | AQ27: BRECANI | AR27: Arjana
A28: 1 | B28: Madame | C28: BRISSON | D28: Amelie | E28: 38 | F28: CAP, BEP | G28: Pierre Goujon | H28: 45917 | I28: 45946 | J28: 45946 | K28: =+J28+180 -> 46126 | N28: =M28+180 -> 180 | O28: Santé mentale | U28: Réorientation | V28: Social freins+ | X28: 46125 | Y28: P267 | AN28: Absence RDV 2 / Mail envoyé le 210126
A29: 1 | B29: Madame | C29: BRUNET | D29: Carole | E29: 37 | F29: CAP, BEP | G29: Croix Blanche | H29: 45812 | I29: 45902 | J29: 45902 | K29: =+J29+180 -> 46082 | L29: Renouvellement | M29: 46083 | N29: =M29+180 -> 46263 | O29: Santé mentale | P29: Permis suspendu | T29: 1 | U29: Fin bilan parcours | V29: FT acc pro | X29: 46267 | Y29: P279 | AN29: REO SOCIALE A ENVISAGER | AP29: SECRETARIAT MEDICAL | AQ29: BRUNET | AR29: Carole | AS29: carolebrunet@orange.fr
A30: 1 | B30: Monsieur | C30: BULINGE | D30: Corentin | E30: 26 | F30: Aucun diplôme | G30: Pierre Goujon | H30: 46057 | I30: 46066 | J30: 46066 | K30: =+J30+180 -> 46246 | N30: =M30+180 -> 180 | U30: Positive | W30: CDI >ou= 24h | X30: 46204 | Y30: P988 | AN30: CDI JUILLET 2026 | AO30: Interim Bressor | AP30: ARMEE DE TERRE | AQ30: BULINGE | AR30: Corentin | AS30: bulingecorentin@gmail.com
A31: 1 | B31: Madame | C31: CALARD | D31: Johanna | E31: 27 | F31: Aucun diplôme | G31: Croix Blanche | H31: 46036 | I31: 46050 | N31: =M31+180 -> 180 | U31: Réorientation | V31: Social freins+ | X31: 46077 | Y31: P1075
A32: 1 | B32: Madame | C32: CAMARA | D32: Mafoudia | E32: 35 | G32: Pierre Goujon | H32: 45826 | I32: 45868 | N32: =M32+180 -> 180 | U32: Radié suite CLI
A33: 1 | B33: Madame | C33: CEESAY | D33: Serra | E33: 26 | F33: Aucun diplôme | G33: Pierre Goujon | H33: 46008 | I33: 46031 | J33: 46031 | K33: =+J33+180 -> 46211 | N33: =M33+180 -> 180 | O33: Langue | P33: Garde enfant | U33: Fin DD | X33: 46113 | Y33: P939 | AN33: CE OK | AO33: RADIATION CAF | AP33: MENAGE
A34: 1 | B34: Monsieur | C34: CESSIN | D34: Patrick | E34: 31 | G34: Pierre Goujon | H34: 45869 | I34: 45924 | K34: =+J34+180 -> 180 | N34: =M34+180 -> 180 | U34: Radié suite CLI | AN34: CLI - pas de nouvelle
A35: 1 | B35: Madame | C35: CHACON COTOS | D35: Yesica | E35: 43 | G35: Pierre Goujon | H35: 45982 | I35: 46000 | J35: 46000 | K35: =+J35+180 -> 46180 | N35: =M35+180 -> 180 | U35: Fin DD | V35: FT acc pro | X35: 46128 | Y35: P360 | AN35: CE OK / BENEFICIAIRE ARE / En attente justif pour réo / Mail envoyé 270226 | AO35: REO FT / DROIT ARE
A36: 1 | B36: Monsieur | C36: CHARNI | D36: Hèdi | E36: 62 | G36: Pierre Goujon | H36: 45846 | I36: 45894 | N36: =M36+180 -> 180 | U36: Réorientation | V36: Social freins+
A37: 1 | B37: Madame | C37: CHOMETTON | D37: Lydie | E37: 34 | F37: CAP, BEP | G37: Pierre Goujon | H37: 45847 | I37: 45860 | J37: 45860 | K37: =+J37+180 -> 46040 | L37: Renouvellement | M37: 46045 | N37: =M37+180 -> 46225 | O37: Santé mentale | R37: 1 | U37: Réorientation | V37: Sociale AAH | X37: 46202 | Y37: P335 | AJ37: 1 | AN37: CE OK / Préco MDPH vers ORSAC a été hospit 3 mois | AO37: Candidature orsac | AP37: ORSAC | AQ37: CHOMETTON | AR37: Lydie | AS37: lilith01volturi@gmail.com
A38: 1 | B38: Madame | C38: COMBEAU | D38: Noémie | G38: Croix Blanche | I38: 45986 | N38: =M38+180 -> 180 | U38: Fin DD | X38: 46083
A39: 1 | B39: Madame | C39: COTOS REGALADO | D39: Nancy | E39: 63 | F39: Aucun diplôme | G39: Croix Blanche | H39: 45832 | I39: 45925 | N39: =M39+180 -> 180 | U39: Réorientation | V39: Sociale retraite | X39: 46023 | Y39: P341
A40: 1 | B40: Monsieur | C40: DAOUD | D40: Boina | E40: 45 | F40: Aucun diplôme | G40: Croix Blanche | H40: 45833 | I40: 45924 | J40: 45924 | K40: =+J40+180 -> 46104 | L40: Renouvellement | M40: 46106 | N40: =M40+180 -> 46286 | O40: Garde enfant | P40: Santé | U40: Fin bilan parcours | V40: FT acco glo | X40: 46290 | Y40: P275 | AN40: REO SOCIALE A ENVISAGER | AO40: ne veut pas faire garder ses enfants | AP40: ESPACE VERTS PROPRETE URBAINE | AQ40: DAOUD | AR40: Boina | AS40: boina.daoud79@gmail.com
A41: 1 | B41: Monsieur | C41: DEMIRKAZIK | D41: Ramazan | E41: 57 | G41: Croix Blanche | H41: 45883 | I41: 45916 | K41: =+J41+180 -> 180 | N41: =M41+180 -> 180 | U41: Radié suite CLI | AN41: CLI pas de nouvelle
...

Sheet Sanctions + absence 
C1: Absence avant signature CE | E1: Absences 2026 cumulées par mois (rdv-atelier-forum-jobdating..) Après signature CE | Q1: Niveau 1 : AVERTISSEMENT AVANT SUSPENSION | W1: Niveau 2 : suspension remobilisation | Z1: Etape 3 : Etape pluridisciplinaire CLI | AA1: 2 eme manquement (process direct etape 3)
A2: Exemple: | C2: 1 | G2: 1 | Q2: 1 | R2: 46084 | S2: 46089 | T2: =S2+15 -> 46104 | U2: 0 | V2: 1 | W2: =T2+35 -> 46139 | X2: 0 | Y2: 1 | Z2: 46147 | AC2: =AB2+35 -> 35
A3: Nom | B3: Prénom | C3: 1ER RDV | D3: 2EME | E3: 1er mois | F3: 2e mois | G3: 3e mois | H3: 4e mois | I3: 5e mois | J3: 6e mois | K3: 7e mois | L3: 8e mois | M3: 9e mois | N3: 10e mois | O3: 11e mois | P3: 12e mois | Q3: Dde etude de situation. | R3: date de la demande | S3: Date courrier CDS (voir extraction transmise) | T3: Délai 15 jours pour contact | U3: Contact BRSA - 15 jours | V3: Mail INFO CDS | W3: Délai de 35 jours pour reprendre contact | X3: le BRSA s'est manifesté ? | Y3: Mail d'info au CDS manifestation ou non dans les 35 jours | Z3: Date CLI si le BRSA ne s'est pas manifesté au bout des 35 jours | AA3: date demande étude de situation (Mail CDS) | AB3: DATE courrier CDS | AC3: 35j pour reprendre contact date butoire | AD3: DATE CLI
A4: ='CROIX BLANCHE PG'!#REF! -> #REF! | B4: ='CROIX BLANCHE PG'!#REF! -> #REF! | C4: 1 | D4: 1 | Q4: 1 | R4: 45960 | T4: =S4+15 -> 15 | W4: =T4+35 -> 50 | AC4: =AB4+35 -> 35
A5: ='CROIX BLANCHE PG'!C9 -> AHMADI | B5: ='CROIX BLANCHE PG'!D9 -> Diba | T5: =S5+15 -> 15 | W5: =S5+50 -> 50 | AC5: =AB5+35 -> 35
A6: ='CROIX BLANCHE PG'!#REF! -> #REF! | B6: ='CROIX BLANCHE PG'!#REF! -> #REF! | C6: 1 | D6: 1 | T6: =S6+15 -> 15 | W6: =S6+50 -> 50 | AC6: =AB6+35 -> 35
A7: ALVES | B7: Merryl
A8: ='CROIX BLANCHE PG'!C13 -> AMARI | B8: ='CROIX BLANCHE PG'!D13 -> Yamina | C8: 1 | T8: =S8+15 -> 15 | W8: =S8+50 -> 50 | AC8: =AB8+35 -> 35
A9: ARARI | B9: Jennifer | Q9: 1 | R9: 45894
A10: ='CROIX BLANCHE PG'!C14 -> ARIFI | B10: ='CROIX BLANCHE PG'!D14 -> Sabrina | T10: =S10+15 -> 15 | W10: =S10+50 -> 50 | AC10: =AB10+35 -> 35
A11: ='CROIX BLANCHE PG'!C16 -> ATHOUMANI | B11: ='CROIX BLANCHE PG'!D16 -> Marie | T11: =S11+15 -> 15 | W11: =S11+50 -> 50 | AC11: =AB11+35 -> 35
A12: AYACH | B12: Samia | G12: 1
A13: ='CROIX BLANCHE PG'!C19 -> BACAR | B13: ='CROIX BLANCHE PG'!D19 -> Mariata | T13: =S13+15 -> 15 | W13: =S13+50 -> 50 | AC13: =AB13+35 -> 35
A14: ='CROIX BLANCHE PG'!C20 -> BAHAR | B14: ='CROIX BLANCHE PG'!D20 -> Laura | T14: =S14+15 -> 15 | W14: =S14+50 -> 50 | AC14: =AB14+35 -> 35
A15: ='BRSA SORTIES'!C15 -> BAITICHE | B15: ='BRSA SORTIES'!D15 -> Karima | T15: =S15+15 -> 15 | W15: =S15+50 -> 50 | AC15: =AB15+35 -> 35
A16: ='CROIX BLANCHE PG'!#REF! -> #REF! | B16: ='CROIX BLANCHE PG'!#REF! -> #REF! | C16: 1 | D16: 1 | Q16: 1 | R16: 45876 | T16: =S16+15 -> 15 | W16: =S16+50 -> 50 | AC16: =AB16+35 -> 35
A17: BASSUS | B17: Jason | F17: 1 | Q17: 1 | R17: 46197 | S17: 46202 | T17: =S17+15 -> 46217
A18: ='CROIX BLANCHE PG'!C25 -> BEKELE | B18: ='CROIX BLANCHE PG'!D25 -> Eteferahu | C18: 1 | T18: =S18+15 -> 15 | W18: =S18+50 -> 50 | AC18: =AB18+35 -> 35
A19: ='CROIX BLANCHE PG'!C26 -> BELFASSI | B19: ='CROIX BLANCHE PG'!D26 -> Maria Dolores | H19: 1 | Q19: 1 | R19: 46133 | S19: 46140 | T19: =S19+15 -> 46155 | W19: =S19+50 -> 46190 | Z19: 46205 | AC19: =AB19+35 -> 35
A20: ='CROIX BLANCHE PG'!C27 -> BENAISSA | B20: ='CROIX BLANCHE PG'!D27 -> Radia | T20: =S20+15 -> 15 | W20: =S20+50 -> 50 | AC20: =AB20+35 -> 35
A21: ='CROIX BLANCHE PG'!C29 -> BEN EL OUALI | B21: ='CROIX BLANCHE PG'!D29 -> Anouar | T21: =S21+15 -> 15 | W21: =S21+50 -> 50 | AC21: =AB21+35 -> 35
A22: BENMELLOUK | B22: Abdelkader | G22: 1
A23: ='CROIX BLANCHE PG'!C31 -> BENOIT | B23: ='CROIX BLANCHE PG'!D31 -> Xavier | C23: 1 | D23: 1 | H23: 1 | Q23: 1 | R23: 46176 | S23: 46204 | T23: =S23+15 -> 46219 | W23: =S23+50 -> 46254 | AC23: =AB23+35 -> 35
A24: ='CROIX BLANCHE PG'!C32 -> BENZEKHROUFA | B24: ='CROIX BLANCHE PG'!D32 -> Abdelghani | F24: 1 | Q24: 1 | R24: 46128 | T24: =S24+15 -> 15 | W24: =S24+50 -> 50 | AC24: =AB24+35 -> 35
A25: ='CROIX BLANCHE PG'!C34 -> BERTHILLOT | B25: ='CROIX BLANCHE PG'!D34 -> Léa | G25: 1 | T25: =S25+15 -> 15 | W25: =S25+50 -> 50 | AC25: =AB25+35 -> 35
A26: ='BRSA SORTIES'!C19 -> BLANC | B26: ='BRSA SORTIES'!D19 -> Mélissa | T26: =S26+15 -> 15 | W26: =S26+50 -> 50 | AC26: =AB26+35 -> 35
A27: ='BRSA SORTIES'!C20 -> BONNET | B27: ='BRSA SORTIES'!D20 -> Cédric | T27: =S27+15 -> 15 | W27: =S27+50 -> 50 | AC27: =AB27+35 -> 35
A28: ='BRSA SORTIES'!C22 -> BOUILLOUX | B28: ='BRSA SORTIES'!D22 -> Nikolas | C28: 1 | T28: =S28+15 -> 15 | W28: =S28+50 -> 50 | AC28: =AB28+35 -> 35
A29: ='CROIX BLANCHE PG'!#REF! -> #REF! | B29: ='CROIX BLANCHE PG'!#REF! -> #REF! | C29: 1 | T29: =S29+15 -> 15 | W29: =S29+50 -> 50 | AC29: =AB29+35 -> 35
A30: ='CROIX BLANCHE PG'!#REF! -> #REF! | B30: ='CROIX BLANCHE PG'!#REF! -> #REF! | C30: 1 | T30: =S30+15 -> 15 | W30: =S30+50 -> 50 | AC30: =AB30+35 -> 35
A31: ='CROIX BLANCHE PG'!#REF! -> #REF! | B31: ='CROIX BLANCHE PG'!#REF! -> #REF! | C31: 1 | D31: 1 | Q31: 1 | R31: 45898 | T31: =S31+15 -> 15 | W31: =S31+50 -> 50 | AC31: =AB31+35 -> 35
A32: ='BRSA SORTIES'!C27 -> BRECANI | B32: ='BRSA SORTIES'!D27 -> Arjana | T32: =S32+15 -> 15 | W32: =S32+50 -> 50 | AC32: =AB32+35 -> 35
A33: ='CROIX BLANCHE PG'!#REF! -> #REF! | B33: ='CROIX BLANCHE PG'!#REF! -> #REF! | T33: =S33+15 -> 15 | W33: =S33+50 -> 50 | AC33: =AB33+35 -> 35
A34: ='BRSA SORTIES'!C29 -> BRUNET | B34: ='BRSA SORTIES'!D29 -> Carole | T34: =S34+15 -> 15 | W34: =S34+50 -> 50 | AC34: =AB34+35 -> 35
A35: ='CROIX BLANCHE PG'!C42 -> BRUZEAU | B35: ='CROIX BLANCHE PG'!D42 -> Laura | T35: =S35+15 -> 15 | W35: =S35+50 -> 50 | AC35: =AB35+35 -> 35
A36: ='CROIX BLANCHE PG'!C43 -> BUATTIER | B36: ='CROIX BLANCHE PG'!D43 -> Christelle | Q36: 1 | R36: 46140 | S36: 46146 | T36: =S36+15 -> 46161 | W36: =S36+50 -> 46196 | Z36: 46205 | AC36: =AB36+35 -> 35
A37: ='CROIX BLANCHE PG'!#REF! -> #REF! | B37: ='CROIX BLANCHE PG'!#REF! -> #REF! | T37: =S37+15 -> 15 | W37: =S37+50 -> 50 | AC37: =AB37+35 -> 35
A38: CAMARA | B38: Mafoudia | Q38: 1 | R38: 45933
A39: ='CROIX BLANCHE PG'!#REF! -> #REF! | B39: ='CROIX BLANCHE PG'!#REF! -> #REF! | T39: =S39+15 -> 15 | W39: =S39+50 -> 50 | AC39: =AB39+35 -> 35
A40: ='CROIX BLANCHE PG'!#REF! -> #REF! | B40: ='CROIX BLANCHE PG'!#REF! -> #REF! | C40: 1 | D40: 1 | Q40: 1 | R40: 45933 | T40: =S40+15 -> 15 | W40: =S40+50 -> 50 | AC40: =AB40+35 -> 35
...

Sheet bilan de parcours  + démarches
A1: Exemples | C1: 5 | D1: 7 | E1: 9 | F1: 12 | G1: 15 | H1: 15 | I1: Renouvellement | J1: 46084 | K1: 1 | L1: 15 | M1: 15 | N1: 15 | O1: 15 | P1: 15 | Q1: 15 | R1: 46268 | S1: Reo FT
C3: nombres de démarches / par semaine | I3: 7 eme mois Bilan fin de parcours | L3: nombres de démarches / par semaine | R3: 14éme mois Bilan définitif
A4: nom | B4: prenom | C4: 1er mois | D4: 2e mois | E4: 3e mois | F4: 4e mois | G4: 5e mois | H4: 6e mois | I4: demande | J4: Date | K4: Renouvellement | L4: 8e mois | M4: 9e mois | N4: 10e mois | O4: 11e mois | P4: 12e mois | Q4: 13e mois | R4: Date | S4: Préco Réo
A5: ='CROIX BLANCHE PG'!#REF! -> #REF! | B5: ='CROIX BLANCHE PG'!#REF! -> #REF!
A6: ='CROIX BLANCHE PG'!C9 -> AHMADI | B6: ='CROIX BLANCHE PG'!D9 -> Diba | C6: 40 | D6: 40 | E6: 40 | I6: Renouvellement | J6: 46114 | K6: 1
A7: ='CROIX BLANCHE PG'!#REF! -> #REF! | B7: ='CROIX BLANCHE PG'!#REF! -> #REF!
A8: ALVES | B8: Merryl
A9: ='CROIX BLANCHE PG'!C13 -> AMARI | B9: ='CROIX BLANCHE PG'!D13 -> Yamina | I9: Renouvellement | J9: 46134 | K9: 1
A10: ='CROIX BLANCHE PG'!C14 -> ARIFI | B10: ='CROIX BLANCHE PG'!D14 -> Sabrina
A11: ='CROIX BLANCHE PG'!C16 -> ATHOUMANI | B11: ='CROIX BLANCHE PG'!D16 -> Marie | I11: Renouvellement | J11: 46115 | K11: 1
A12: ='CROIX BLANCHE PG'!C19 -> BACAR | B12: ='CROIX BLANCHE PG'!D19 -> Mariata | C12: 60 | D12: 60 | E12: 60 | F12: 60 | G12: 60 | H12: 60 | I12: Renouvellement | J12: 46143 | K12: 1
A13: ='CROIX BLANCHE PG'!C20 -> BAHAR | B13: ='CROIX BLANCHE PG'!D20 -> Laura
A14: ='BRSA SORTIES'!C15 -> BAITICHE | B14: ='BRSA SORTIES'!D15 -> Karima | C14: 10 | D14: 10 | E14: 10 | I14: Renouvellement | J14: 46055 | K14: 1
A15: ='CROIX BLANCHE PG'!#REF! -> #REF! | B15: ='CROIX BLANCHE PG'!#REF! -> #REF!
A16: BASSUS | B16: Jason
A17: ='CROIX BLANCHE PG'!C25 -> BEKELE | B17: ='CROIX BLANCHE PG'!D25 -> Eteferahu
A18: ='CROIX BLANCHE PG'!C26 -> BELFASSI | B18: ='CROIX BLANCHE PG'!D26 -> Maria Dolores | C18: 20 | D18: 20
A19: ='CROIX BLANCHE PG'!C27 -> BENAISSA | B19: ='CROIX BLANCHE PG'!D27 -> Radia | C19: 60 | D19: 60 | I19: Renouvellement | J19: 46163 | K19: 1
A20: ='CROIX BLANCHE PG'!C29 -> BEN EL OUALI | B20: ='CROIX BLANCHE PG'!D29 -> Anouar
A21: BENMELLOUK BENMESSA
A22: ='CROIX BLANCHE PG'!C31 -> BENOIT | B22: ='CROIX BLANCHE PG'!D31 -> Xavier
A23: ='CROIX BLANCHE PG'!C32 -> BENZEKHROUFA | B23: ='CROIX BLANCHE PG'!D32 -> Abdelghani
A24: BERGET
A25: ='CROIX BLANCHE PG'!C34 -> BERTHILLOT | B25: ='CROIX BLANCHE PG'!D34 -> Léa
A26: ='BRSA SORTIES'!C19 -> BLANC | B26: ='BRSA SORTIES'!D19 -> Mélissa | I26: Renouvellement | J26: 46052 | K26: 1
A27: ='BRSA SORTIES'!C20 -> BONNET | B27: ='BRSA SORTIES'!D20 -> Cédric | C27: 10 | D27: 10 | E27: 10 | I27: Renouvellement | J27: 46044 | K27: 1
A28: ='BRSA SORTIES'!C22 -> BOUILLOUX | B28: ='BRSA SORTIES'!D22 -> Nikolas
A29: ='CROIX BLANCHE PG'!#REF! -> #REF! | B29: ='CROIX BLANCHE PG'!#REF! -> #REF!
A30: ='CROIX BLANCHE PG'!#REF! -> #REF! | B30: ='CROIX BLANCHE PG'!#REF! -> #REF!
A31: BOYRAZ
A32: ='BRSA SORTIES'!C27 -> BRECANI | B32: ='BRSA SORTIES'!D27 -> Arjana | C32: 60 | D32: 60 | E32: 60 | I32: Renouvellement | J32: 46053 | K32: 1
A33: ='BRSA SORTIES'!C29 -> BRUNET | B33: ='BRSA SORTIES'!D29 -> Carole | I33: Renouvellement | J33: 46083
A34: ='CROIX BLANCHE PG'!C42 -> BRUZEAU | B34: ='CROIX BLANCHE PG'!D42 -> Laura | I34: Tripartite | J34: 46112
A35: ='CROIX BLANCHE PG'!C43 -> BUATTIER | B35: ='CROIX BLANCHE PG'!D43 -> Christelle
A36: ='CROIX BLANCHE PG'!#REF! -> #REF! | B36: ='CROIX BLANCHE PG'!#REF! -> #REF!
A37: ='CROIX BLANCHE PG'!#REF! -> #REF! | B37: ='CROIX BLANCHE PG'!#REF! -> #REF!
A38: ='CROIX BLANCHE PG'!C45 -> CHARNAY | B38: ='CROIX BLANCHE PG'!D45 -> Cindy
A39: ='CROIX BLANCHE PG'!C46 -> CHAVE | B39: ='CROIX BLANCHE PG'!D46 -> Baptiste | C39: 60 | D39: 60 | E39: 60 | F39: 60 | G39: 60 | H39: 60 | I39: Renouvellement | J39: 46114 | K39: 1
A40: ='CROIX BLANCHE PG'!#REF! -> #REF! | B40: ='CROIX BLANCHE PG'!#REF! -> #REF! | C40: 60 | D40: 60 | E40: 60 | F40: 60 | G40: 60 | H40: 60 | I40: Renouvellement | J40: 46100 | K40: 1
A41: ='BRSA SORTIES'!C40 -> DAOUD | B41: ='BRSA SORTIES'!D40 -> Boina | C41: 20 | D41: 20 | E41: 20 | F41: 20 | G41: 20 | H41: 20 | I41: Renouvellement | J41: 46106 | K41: 1
...

Sheet Tableau croisé NE PAS TOUCHER 
A3: Sanction et Absence | E3: Bilan de parcours + démarches
A4: Nombre de 1ER RDV | B4: 32 | E4: Somme de 1er mois | F4: 1540
A5: Somme de 2EME | B5: 20 | E5: Somme de 2e mois | F5: 1390
A6: Nombre de 1er mois | E6: Somme de 3e mois | F6: 1090
A7: Nombre de 2e mois | E7: Somme de 4e mois | F7: 500
A8: Somme de 3e mois | E8: Somme de 5e mois | F8: 420
A9: Somme de 4e mois | E9: Somme de 6e mois | F9: 160
A10: Somme de 5e mois | E10: Nombre de demande
A11: Nombre de 6e mois | E11: Somme de Renouvellement
A12: Nombre de 7e mois | E12: Somme de 8e mois
A13: Nombre de 8e mois | E13: Somme de 9e mois
A14: Nombre de 9e mois | E14: Somme de 10e mois
A15: Nombre de 10e mois | E15: Somme de 11e mois
A16: Nombre de 11e mois | E16: Somme de 12e mois
A17: Nombre de 12e mois | E17: Somme de Préco Réo
A18: Somme de date demande étude de situation (Mail CDS)
A19: Somme de Dde etude de situation.
A21: Valeurs | C21: SEXE | D21: Nombre de H/F | E21: SORTIES | F21: Nombre de Motif de sortie | G21: Nombre de MOTIF de la REO
A22: Moyenne de âge | B22: 40.956044 | C22: Madame | D22: 114 | E22: Déménagement | F22: 3
A23: Nombre de C.E SIGNE | B23: 126 | C23: Monsieur | D23: 71 | E23: (vide) | F23: 3
A24: Nombre de BILAN PARCOURS (7eme mois) | B24: 55 | C24: (vide) | E24: Fin DD | F24: 8 | G24: 2
A25: Somme de PMSMP (1 = oui) | B25: 1 | C25: Total général | D25: 185 | E25: FT acc pro | F25: 2 | G25: 2
A26: Nombre de H/F | B26: 185 | E26: (vide) | F26: 6
A27: Nombre de Saisie FSE | B27: 123 | E27: Positive | F27: 10 | G27: 7
A28: Nombre de AIDE FINANCIERE | E28: BGE | F28: 3 | G28: 3
E29: FT acc pro | F29: 4 | G29: 4
E30: (vide) | F30: 3
A31: SORTIES POSITIVES | B31: Nombre de types | E31: Renonciation RSA | F31: 1
A32: CDI >ou= 24h | B32: 3 | E32: (vide) | F32: 1
A33: Créa | B33: 5 | E33: Réorientation | F33: 42 | G33: 42
A34: (vide) | E34: BGE | F34: 5 | G34: 5
A35: SIAE (FT) | B35: 3 | E35: FT acc pro | F35: 5 | G35: 5
A36: France Travail | B36: 1 | E36: Social freins+ | F36: 24 | G36: 24
A37: Stagiaire de la formation | B37: 1 | E37: Sociale retraite | F37: 4 | G37: 4
A38: Total général | B38: 13 | E38: Sociale maternité | F38: 4 | G38: 4
E39: (vide)
E40: (vide)
E41: Radié suite CLI | F41: 12
E42: (vide) | F42: 12
E43: Total général | F43: 76 | G43: 51

Sheet liste deroulante
A1: Années après le Bac | B1: Titre du diplôme | C1: Niveau de diplôme | F1: Réorientation | H1: Motifs Sorties | J1: Sorties
B2: Aucun diplôme | F2: Sociale AAH | G2: Emploi | H2: Positive | J2: CDI >ou= 24h
A3: - | B3: CAP, BEP | C3: 3 (anciennement V) | E3: H | F3: Sociale retraite | G3: Formation | H3: Réorientation | J3: CDD +6mois >ou=254h
A4: Bac | B4: Baccalauréat | C4: 4 (anciennement IV) | E4: F | F4: Sociale maternité | G4: Créa entreprise | H4: Déménagement | J4: Créa
A5: Bac+2 | B5: DEUG, BTS, DUT, DEUST | C5: 5 (anciennement III) | F5: Social freins+ | G5: France Travail | H5: Fin DD | J5: Interim>ou= à 970h cumulées / an
A6: Bac+3 | B6: Licence, licence professionnelle | C6: 6 (anciennement II) | F6: Arret mal longue durée | H6: Décès | J6: Stagiaire de la formation
A7: Bac+4 | B7: Maîtrise, master 1 | C7: 6 (anciennement II) | F7: BGE | H7: Renonciation RSA | J7: SIAE (FT)
A8: Bac+5 | B8: Master, diplôme d'études approfondies, diplôme d'études supérieures spécialisées, diplôme d'ingénieur | C8: 7 (anciennement I) | F8: MSA | H8: Incarcération
A9: Bac+8 | B9: Doctorat, habilitation à diriger des recherches | C9: 8 (anciennement I) | F9: FT acc pro | H9: Mauvaise orientation
F10: FT acco glo | H10: Fin bilan parcours
D11: CLI | H11: Radié suite CLI
B12: freins | D12: 1
B13: mobilité | D13: 0
B14: garde enfants
E15: OUI
A16: CDS | B16: Oyonnax | E16: NON | G16: Resultat bilan parcours
B17: Nantua | G17: Réo FT | H17: Reo FT
B18: Belley | G18: Renouvellement | H18: Réo sociale
B19: Valserhone | G19: Tripartite
B20: Pays de Gex | G20: BGE
B21: Croix Blanche
B22: Pierre Goujon
B23: Montrevel
B24: Pont de Vaux
B25: St Didier sur Chalaronne
B26: Trevoux
B27: Chatillon sur Chalaronne
B28: Amberieu
B29: Lagnieu
B30: Miribel

Sheet CODIFICATION ACTIVITE
A3: Besoin
A4: Ordre | B4: Code | C4: Libellé | D4: Libellé | E4: Libellé | F4: Volume horaire Hedbomadaire
A5: 1 | B5: P01 | C5: Choisir un métier | D5: Identification de ses points forts et de ses compétences | E5: Identifier ses points forts et ses compétences | F5: 3
D6: Information sur un métier ou un secteur d'activité | E6: S'informer sur un métier ou un secteur d'activité | F6: 3
D7: Observation en entreprise | E7: Réaliser une observation en entreprise | F7: 3
D8: Enquête métier afin de mieux connaître un métier | E8: Réaliser une enquête métier | F8: 3
D9: Participation à un salon ou un forum pour s'informer sur un métier | E9: Participer à un salon ou un forum pour s'informer sur un métier | F9: 3
A10: 2 | B10: P02 | C10: Se former | D10: Information sur un projet de formation ou de Validation des acquis de l'expérience | E10: S'informer sur un projet de formation ou de validation des acquis de l'expérience | F10: 3
D11: Montage d'un dossier d’inscription à une formation | E11: Monter son dossier de formation | F11: 3
D12: Participation à une formation | E12: Participer à une formation | F12: 35
D13: Participation à un salon ou un forum formation | E13: Participer à un salon ou un forum formation | F13: 3
D14: Initiation à l'informatique ou à Internet | E14: S'initier à l'informatique ou à Internet | F14: 3
D15: Participation à un dispositif d'insertion | E15: Participer à un dispositif d'insertion | F15: 35
A16: 3 | B16: P03 | C16: Préparer sa candidature | D16: Réalisation d'une démarche de VAE | E16: Réaliser une démarche de VAE | F16: 3
D17: Préparation de ses candidatures (CV, lettre de motivation, book) | E17: Réaliser ou mettre à jour son CV sa lettre de motivation ou son portfolio | F17: 3
E18: Développer son réseau | F18: 3
E19: S'inscrire ou compléter son profil sur un réseau professionnel | F19: 3
E20: Réaliser des activités de bénévolat | F20: 5
E21: Organiser ses démarches de recherche d’emploi | F21: 3
E22: Compléter ou publier son profil de compétence | F22: 3
A23: 4 | C23: Trouver un emploi | D23: Recherche d'offres d'emploi ou d'entreprises | E23: Rechercher des offres d'emploi ou d'entreprises | F23: 3
D24: Participation à un salon ou un forum pour rechercher des offres | E24: Participer à un salon ou un forum pour rechercher des offres d'emploi | F24: 3
D25: Réponse à des offres d'emploi | E25: Répondre à des offres d'emploi | F25: 3
D26: Candidatures spontanées | E26: Effectuer des candidatures spontanées | F26: 3
D27: Réalisation du suivi de ses candidatures et relance des recruteurs | E27: Réaliser le suivi de ses candidatures et relancer des recruteurs | F27: 3
D28: Préparation des entretiens d'embauche | E28: Préparer un entretien d'embauche | F28: 3
D29: Réalisation d'entretiens d'embauche | E29: Réaliser un entretien d'embauche | F29: 3
D30: Passation de tests de recrutement (concours, casting…) | E30: Passer des tests de recrutement (concours, casting…) | F30: 3
D31: Réalisation d'une mise en situation professionnelle dans une entreprise | E31: Réaliser une mise en situation professionnelle dans une entreprise | F31: 35
D32: Recherche de missions de service civique | E32: Rechercher des missions de service civique | F32: 3
E33: S'inscrire sur une plateforme de recrutement (agence d'intérim, cabinet de recrutement, site spécialisé…) | F33: 3
A34: 5 | B34: P05 | C34: Ma création et reprise d'entreprise | D34: Recherches pour créer ou reprendre une entreprise | E34: Effectuer des recherches pour créer ou reprendre une entreprise | F34: 3
D35: Réalisation d'une étude de marché auprès de prospects/clients /fournisseurs | E35: Réaliser une étude de marché auprès de prospects/clients /fournisseurs | F35: 3
D36: Participation à un salon ou forum pour s'informer sur la création entreprise | E36: Participer à un salon ou forum pour s'informer sur la création d'entreprise | F36: 3
D37: Réalisation d'un business plan afin de préparer la création de son entreprise | E37: Réaliser un business plan afin de préparer la création de son entreprise | F37: 3
D38: Prise de RDV avec des organismes financiers | E38: Prendre rendez-vous avec des organismes financiers | F38: 3
D39: Réalisation de démarches juridiques de création d'entreprise | E39: Réaliser des démarches juridiques de création d'entreprise | F39: 3
D40: Réalisation d'actions de communication pour faire connaitre son entreprise | E40: Réaliser des actions de communication pour faire connaître son entreprise | F40: 3
D41: Prospection pour développer sa clientèle | E41: Prospecter pour développer sa clientèle | F41: 3
D42: Développement de nouveaux partenariats | E42: Développer de nouveaux partenariats | F42: 3
...

Sheet Feuil1
A1: Nom | B1: Prénom | C1: 1er mois | D1: 2e mois | E1: 3e mois | F1: 4e mois | G1: 5e mois | H1: 6e mois | I1: 7e mois | J1: 8e mois | K1: 9e mois | L1: 10e mois | M1: 11e mois | N1: 12e mois | O1: Dde etude de situation. | P1: date de la demande | Q1: Date courrier CDS (voir extraction transmise) | R1: Délai 15 jours pour contact | S1: Contact BRSA - 15 jours | T1: Mail INFO CDS | U1: Délai de 35 jours pour reprendre contact | V1: le BRSA s'est manifesté ? | W1: Mail d'info au CDS manifestation ou non dans les 35 jours | X1: Date CLI si le BRSA ne s'est pas manifesté au bout des 35 jours | Y1: date demande étude de situation (Mail CDS) | Z1: DATE courrier CDS | AA1: 35j pour reprendre contact date butoire | AB1: DATE CLI
A2: AHAMADA | B2: Fatima | E2: 1 | F2: 1 | O2: 1 | P2: 46052 | Q2: 46057 | R2: 46072 | S2: 0 | T2: 1 | U2: 46107 | Y2: 1 | Z2: 46122 | AA2: 46157
A3: XHAFAJ | B3: IGBALLE | R3: 15 | U3: 50 | AA3: 35
A4: AKKAOUI | B4: Badr | O4: 1 | P4: 46049 | Q4: 46054 | R4: 46069 | U4: 46104 | AA4: 35
A5: ALI ABDULLEH | B5: Maymoun | R5: 15 | U5: 50 | AA5: 35
A6: AMIRAT | B6: Saliha | R6: 15 | U6: 50 | AA6: 35
A7: BA | B7: N Dela | F7: 1 | G7: 1 | O7: 1 | P7: 46049 | Q7: 46054 | R7: 46069 | S7: 1 | T7: 1 | U7: 46104 | AA7: 35
A8: BAKHTOKHIL | B8: Hayatullah | E8: 5 | R8: 15 | U8: 50 | AA8: 35
A9: BAUDHUIN | B9: Claire | G9: 5 | R9: 15 | U9: 50 | AA9: 35
A10: BENOIT GONIN | B10: Lucas | R10: 15 | U10: 50 | AA10: 35
A11: BOUJLOUD | B11: Zeneb | R11: 15 | U11: 50 | AA11: 35
A12: CANI | B12: Rilinda | R12: 15 | U12: 50 | AA12: 35
A13: CELEBI | B13: Bekir | G13: 5 | R13: 15 | U13: 50 | AA13: 35
A14: CERVANTES | B14: Sabrina | R14: 15 | U14: 50 | AA14: 35
A15: CHANAL-MOGUET | B15: Virginie | D15: 5 | R15: 15 | U15: 50 | AA15: 35
A16: CHAUME | B16: Stephanie | R16: 15 | U16: 50 | AA16: 35
A17: DAMIRON | B17: Arthur | O17: 1 | P17: 46049 | Q17: 46054 | R17: 46069 | S17: 1 | T17: 1 | U17: 46104 | AA17: 35
A18: EL ARKOUBI | B18: Touria | R18: 15 | U18: 50 | AA18: 35
A19: EL BAHMANI | B19: Naima | R19: 15 | U19: 50 | AA19: 35
A20: ERASLAN | B20: Eren | O20: 1 | P20: 46049 | Q20: 46054 | R20: 46069 | U20: 46104 | AA20: 35
A21: GILBERT | B21: Stéphanie | R21: 15 | U21: 50 | AA21: 35
A22: HIDA | B22: Soumaya | O22: 1 | P22: 46049 | Q22: 46054 | R22: 46069 | U22: 46104 | AA22: 35
A23: HUMBERT | B23: Jolan | O23: 1 | P23: 46049 | Q23: 46054 | R23: 46069 | U23: 46104 | AA23: 35
A24: KABA | B24: M'balou | R24: 15 | U24: 50 | AA24: 35
A25: KACEM | B25: Houaria | R25: 15 | U25: 50 | AA25: 35
A26: KASEMRATH | B26: Melanie | R26: 15 | U26: 50 | AA26: 35
A27: LAHJAR | B27: Nadia | R27: 15 | U27: 50 | AA27: 35
A28: LAHU | B28: Fabien | R28: 15 | U28: 50 | AA28: 35
A29: LAZRAK | B29: Rajae | R29: 15 | U29: 50 | AA29: 35
A30: MALKI | B30: Hanane | R30: 15 | U30: 50 | AA30: 35
A31: MITKOVA | B31: Marusya | O31: 1 | P31: 46049 | Q31: 46054 | R31: 46069 | S31: 1 | T31: 1 | U31: 46104 | AA31: 35
A32: M'MADI | B32: Zaidine | R32: 15 | U32: 50 | AA32: 35
A33: PATEL | B33: Virginie | R33: 15 | U33: 50 | AA33: 35
A34: ROBERT | B34: Olivier | R34: 15 | U34: 50 | AA34: 35
A35: SIOUDA | B35: Tourkia | R35: 15 | U35: 50 | AA35: 35
A36: SOEUM | B36: Justine | R36: 15 | U36: 50 | AA36: 35
A37: SOUCANE | B37: Pascale | R37: 15 | U37: 50 | AA37: 35
A38: SYED RASHAD | B38: Ayesha | R38: 15 | U38: 50 | AA38: 35
A39: YILMAZ | B39: Talip | R39: 15 | U39: 50 | AA39: 35
A40: AIT YOUSSEF | B40: Maryam | R40: 15 | U40: 50 | AA40: 35
...
